Workbook

Sheet LEAME
A1: Ingeniería inversa – Metodología AM Best 'Life Settlement Securitization' (SPV USD 100 mm)
A2: Réplica independiente del proceso descrito públicamente por AM Best. NO es el modelo propietario ni una calificación de AM Best.
A4: Proceso replicado (en el orden que AM Best lo describe)
A5: 1. Filtros de elegibilidad: ~300 vidas, ≤3.33% del face por vida, ≥2 proveedores de LE, LE ≤12 meses, cartera adquirida antes de calificar.
A6: 2. Mortalidad: tabla base (2015 VBT en la revisión 2026) × calificación de mortalidad del underwriter, ajustada por
A7: Basic Adjustment Factor (nivel de la calificación y si la póliza fue premium-financed), Age-Based Adjustment Factor y Ratings Wear-Off.
A8: 3. Simulación Monte Carlo de muertes (con choque sistemático por error de estimación de LE), default de aseguradoras y caducidad por falta de liquidez.
A9: 4. Probabilidad de default de cada nota vs. su vencimiento esperado → Matriz Idealizada de Default (BILSM, Exhibit E.2) → calificación.
A10: 5. Escenarios de estrés y factores cualitativos → ajuste en notches para el comité.
A12: Cómo usarlo
A13: a) Pegue su cinta póliza por póliza en 'Cartera_Polizas' (columnas azules). Las columnas negras se calculan solas.
A14: b) Reemplace 'Tabla_Mortalidad' por la 2015 VBT real (q_x por edad) y 'Matriz_Default' por el Exhibit E.2 de BILSM.
... A19: Los valores de BAF, AAF, wear-off, sigma sistemática y la matriz de default son ESTIMACIONES: AM Best describe estos factores pero sus tablas no fueron accesibles.

Sheet Resultados_MC
A1: Resultados Monte Carlo y calificación indicada (réplica – no es una calificación de AM Best)
A2: Valores en columnas B–K los escribe el motor (python ambest_ls_model.py run). Columnas L–Q son fórmulas contra 'Matriz_Default'.
A3: Estado: | B3: Corrido: 5000 simulaciones, 300 pólizas, semilla 2026
A5: Escenario | B5: PD Senior | C5: Pérdida esperada Senior | D5: Vencim. esperado Senior (años) | E5: PD Mezz | F5: Pérdida esperada Mezz | G5: Vencim. esperado Mezz (años) | H5: P(caducidad con notas vigentes) | I5: LE realizada prom. (años) | J5: Muertes cobradas prom. (USD mm) | K5: Sims | L5: Senior – índice | M5: Senior – calificación MC | N5: Mezz – índice | O5: Mezz – calificación MC | P5: Senior – final (con notches) | Q5: Mezz – final (con notches)
A6: =Escenarios!A6 -> Base | B6: 0.0324 | C6: 0.018875285 | D6: 4.3893644 | E6: 0.0418 | F6: 0.036668659 | G6: 7.8933436 | H6: 0.0112 | I6: 7.6576057 | J6: 441.86747 | K6: 5000 | L6: =IF(B6="","",COUNTIF(INDEX(Matriz_Default!$C$5:$AF$20,0,MIN(30,MAX(1,ROUND(D6,0)))),"<"&B6)+1) -> 9 | M6: =IF(L6="","",INDEX(Matriz_Default!$A$5:$A$21,MIN(17,L6))) -> bbb | N6: =IF(E6="","",MAX(L6,COUNTIF(INDEX(Matriz_Default!$C$5:$AF$20,0,MIN(30,MAX(1,ROUND(G6,0)))),"<"&E6)+1)) -> 9 | O6: =IF(N6="","",INDEX(Matriz_Default!$A$5:$A$21,MIN(17,N6))) -> bbb | P6: =IF(L6="","",INDEX(Matriz_Default!$A$5:$A$21,MIN(17,L6-Ponderacion!$C$28))) -> bbb- | Q6: =IF(N6="","",INDEX(Matriz_Default!$A$5:$A$21,MIN(17,N6-Ponderacion!$C$28))) -> bbb-
A7: =Escenarios!A7 -> Extensión LE (q × 0.85) | B7: 0.1352 | C7: 0.087421669 | D7: 7.7271989 | E7: 0.1674 | F7: 0.15202808 | G7: 12.005471 | H7: 0.0488 | I7: 8.5347457 | J7: 435.37259 | K7: 5000 | L7: =IF(B7="","",COUNTIF(INDEX(Matriz_Default!$C$5:$AF$20,0,MIN(30,MAX(1,ROUND(D7,0)))),"<"&B7)+1) -> 11 | M7: =IF(L7="","",INDEX(Matriz_Default!$A$5:$A$21,MIN(17,L7))) -> bb+ | N7: =IF(E7="","",MAX(L7,COUNTIF(INDEX(Matriz_Default!$C$5:$AF$20,0,MIN(30,MAX(1,ROUND(G7,0)))),"<"&E7)+1)) -> 11 | O7: =IF(N7="","",INDEX(Matriz_Default!$A$5:$A$21,MIN(17,N7))) -> bb+ | P7: =IF(L7="","",INDEX(Matriz_Default!$A$5:$A$21,MIN(17,L7-Ponderacion!$C$28))) -> bb | Q7: =IF(N7="","",INDEX(Matriz_Default!$A$5:$A$21,MIN(17,N7-Ponderacion!$C$28))) -> bb
A8: =Escenarios!A8 -> Extensión severa (q × 0.75) | B8: 0.3056 | C8: 0.21627372 | D8: 11.816442 | E8: 0.3496 | F8: 0.32757599 | G8: 15.94245 | H8: 0.1354 | I8: 9.2435037 | J8: 423.82575 | K8: 5000 | L8: =IF(B8="","",COUNTIF(INDEX(Matriz_Default!$C$5:$AF$20,0,MIN(30,MAX(1,ROUND(D8,0)))),"<"&B8)+1) -> 13 | M8: =IF(L8="","",INDEX(Matriz_Default!$A$5:$A$21,MIN(17,L8))) -> bb- | N8: =IF(E8="","",MAX(L8,COUNTIF(INDEX(Matriz_Default!$C$5:$AF$20,0,MIN(30,MAX(1,ROUND(G8,0)))),"<"&E8)+1)) -> 13 | O8: =IF(N8="","",INDEX(Matriz_Default!$A$5:$A$21,MIN(17,N8))) -> bb- | P8: =IF(L8="","",INDEX(Matriz_Default!$A$5:$A$21,MIN(17,L8-Ponderacion!$C$28))) -> b+ | Q8: =IF(N8="","",INDEX(Matriz_Default!$A$5:$A$21,MIN(17,N8-Ponderacion!$C$28))) -> b+
A9: =Escenarios!A9 -> Primas +1.5% anual adicional | B9: 0.067 | C9: 0.04069154 | D9: 5.1278532 | E9: 0.0884 | F9: 0.076602736 | G9: 8.8358663 | H9: 0.0304 | I9: 7.6576057 | J9: 441.20079 | K9: 5000 | L9: =IF(B9="","",COUNTIF(INDEX(Matriz_Default!$C$5:$AF$20,0,MIN(30,MAX(1,ROUND(D9,0)))),"<"&B9)+1) -> 11 | M9: =IF(L9="","",INDEX(Matriz_Default!$A$5:$A$21,MIN(17,L9))) -> bb+ | N9: =IF(E9="","",MAX(L9,COUNTIF(INDEX(Matriz_Default!$C$5:$AF$20,0,MIN(30,MAX(1,ROUND(G9,0)))),"<"&E9)+1)) -> 11 | O9: =IF(N9="","",INDEX(Matriz_Default!$A$5:$A$21,MIN(17,N9))) -> bb+ | P9: =IF(L9="","",INDEX(Matriz_Default!$A$5:$A$21,MIN(17,L9-Ponderacion!$C$28))) -> bb | Q9: =IF(N9="","",INDEX(Matriz_Default!$A$5:$A$21,MIN(17,N9-Ponderacion!$C$28))) -> bb
A10: =Escenarios!A10 -> Default aseguradora mayor | B10: 0.1278 | C10: 0.077630238 | D10: 6.98016 | E10: 0.1596 | F10: 0.14455283 | G10: 11.149848 | H10: 0.0518 | I10: 7.6576057 | J10: 400.31921 | K10: 5000 | L10: =IF(B10="","",COUNTIF(INDEX(Matriz_Default!$C$5:$AF$20,0,MIN(30,MAX(1,ROUND(D10,0)))),"<"&B10)+1) -> 12 | M10: =IF(L10="","",INDEX(Matriz_Default!$A$5:$A$21,MIN(17,L10))) -> bb | N10: =IF(E10="","",MAX(L10,COUNTIF(INDEX(Matriz_Default!$C$5:$AF$20,0,MIN(30,MAX(1,ROUND(G10,0)))),"<"&E10)+1)) -> 12 | O10: =IF(N10="","",INDEX(Matriz_Default!$A$5:$A$21,MIN(17,N10))) -> bb | P10: =IF(L10="","",INDEX(Matriz_Default!$A$5:$A$21,MIN(17,L10-Ponderacion!$C$28))) -> bb- | Q10: =IF(N10="","",INDEX(Matriz_Default!$A$5:$A$21,MIN(17,N10-Ponderacion!$C$28))) -> bb-
A11: =Escenarios!A11 -> Liquidez −50% | B11: 0.0594 | C11: 0.033045875 | D11: 5.6204669 | E11: 0.0734 | F11: 0.06490962 | G11: 9.2008381 | H11: 0.021 | I11: 7.6576057 | J11: 441.35707 | K11: 5000 | L11: =IF(B11="","",COUNTIF(INDEX(Matriz_Default!$C$5:$AF$20,0,MIN(30,MAX(1,ROUND(D11,0)))),"<"&B11)+1) -> 10 | M11: =IF(L11="","",INDEX(Matriz_Default!$A$5:$A$21,MIN(17,L11))) -> bbb- | N11: =IF(E11="","",MAX(L11,COUNTIF(INDEX(Matriz_Default!$C$5:$AF$20,0,MIN(30,MAX(1,ROUND(G11,0)))),"<"&E11)+1)) -> 10 | O11: =IF(N11="","",INDEX(Matriz_Default!$A$5:$A$21,MIN(17,N11))) -> bbb- | P11: =IF(L11="","",INDEX(Matriz_Default!$A$5:$A$21,MIN(17,L11-Ponderacion!$C$28))) -> bb+ | Q11: =IF(N11="","",INDEX(Matriz_Default!$A$5:$A$21,MIN(17,N11-Ponderacion!$C$28))) -> bb+
A13: CALIFICACIÓN INDICADA (caso base MC − notches cualitativos y de elegibilidad)
A14: Senior | B14: =P6 -> bbb-
A15: Mezzanine | B15: =Q6 -> bbb-
A16: Notches aplicados | B16: =Ponderacion!C28 -> -1
A18: Conciliación: LE ponderada Excel vs. motor | B18: =Cartera_Polizas!I3 -> 7.5267385 | C18: 7.5267385 | D18: =IF(C18="","",IF(ABS(B18-C18)<0.05,"OK","REVISAR")) -> OK

Sheet Supuestos
A1: Supuestos
B3: Parámetro | C3: Valor | D3: Unidad | E3: Fuente / estatus
B5: Notas Senior | C5: 75 | D5: USD mm | E5: Estructura ilustrativa
B6: Cupón Senior | C6: 0.065 | D6: % anual | E6: Estructura ilustrativa
B7: Notas Mezzanine | C7: 25 | D7: USD mm | E7: Estructura ilustrativa
B8: Cupón Mezzanine | C8: 0.095 | D8: % anual | E8: Estructura ilustrativa
B9: Reserva de liquidez inicial (equity) | C9: 20 | D9: USD mm | E9: Estructura ilustrativa
B10: Reserva objetivo (meses de primas + gastos) | C10: 12 | D10: meses | E10: Práctica de mercado
B11: Tasa de reinversión de caja | C11: 0.03 | D11: % anual | E11: Supuesto
B12: Gastos fijos (servicer, trustee, tracking) | C12: 0.75 | D12: USD mm/año | E12: Supuesto
B13: Gasto variable sobre face en vigor | C13: 0.0005 | D13: % anual | E13: Supuesto
B14: Venta de cartera remanente al vencimiento legal | C14: 0.2 | D14: % face | E14: Supuesto (AM Best suele dar poco crédito)
B15: Vencimiento legal (años, máx. 40) | C15: 25 | D15: años | E15: Estructura ilustrativa
B16: Número de simulaciones Monte Carlo | C16: 5000 | D16: # | E16: Motor (AM Best: Monte Carlo)
... B27: Mínimo de proveedores de LE | C27: 2 | D27: # | E27: AM Best (publicado)

Sheet Factores
A1: Factores de ajuste de mortalidad y riesgo de aseguradoras
A2: Estructura descrita por AM Best; los valores son estimaciones a calibrar (factor < 1 reduce la mortalidad = extiende la LE).
A4: Basic Adjustment Factor (BAF) – por nivel de calificación de mortalidad y premium financing
A5: MR desde (≥) | B5: BAF no PF | C5: BAF premium-financed
A6: 0 | B6: 0.95 | C6: 0.9
A7: 1.5 | B7: 0.88 | C7: 0.82
A8: 3 | B8: 0.8 | C8: 0.74
A9: 5 | B9: 0.72 | C9: 0.66
A11: Age-Based Adjustment Factor (AAF)
A12: Edad desde (≥) | B12: AAF
A13: 0 | B13: 0.9
A14: 75 | B14: 0.95
A15: 85 | B15: 1
A16: 90 | B16: 1
A18: PD anual de aseguradoras por FSR
A19: FSR | B19: PD anual
A20: A++ | B20: 0.0001
A21: A+ | B21: 0.0003
A22: A | B22: 0.0006
A23: A- | B23: 0.001
A24: B++ | B24: 0.0025
A25: B+ | B25: 0.005
A27: Aseguradoras de la cartera
A28: ID | B28: Nombre | C28: FSR
A29: 1 | B29: Aseguradora 1 | C29: A+
A30: 2 | B30: Aseguradora 2 | C30: A+
A31: 3 | B31: Aseguradora 3 | C31: A
A32: 4 | B32: Aseguradora 4 | C32: A
A33: 5 | B33: Aseguradora 5 | C33: A-
A34: 6 | B34: Aseguradora 6 | C34: A
A35: 7 | B35: Aseguradora 7 | C35: A+
A36: 8 | B36: Aseguradora 8 | C36: B++

Sheet Tabla_Mortalidad
A1: Tabla base de mortalidad q_x (proxy Gompertz – REEMPLAZAR por 2015 VBT)
A2: Proxy: μ(x) = 0.07·e^{0.11(x−85)}, q = 1−e^{−μ}; q(120) = 1. La revisión 2026 de AM Best usa 2015 VBT.
A4: Edad | B4: q_x
A5: 50 | B5: 0.001488
A6: 51 | B6: 0.001661
A7: 52 | B7: 0.001854
A8: 53 | B8: 0.00207
A9: 54 | B9: 0.00231
A10: 55 | B10: 0.002578
A11: 56 | B11: 0.002878
A12: 57 | B12: 0.003212
A13: 58 | B13: 0.003585
A14: 59 | B14: 0.004001
A15: 60 | B15: 0.004465
A16: 61 | B16: 0.004983
... A75: 120 | B75: 1

Sheet Cartera_Polizas
A1: Cinta de datos póliza por póliza (ejemplo sintético de 300 vidas – reemplazar)
A2: Columnas A–L = input. M–R = fórmulas (ajustes de AM Best replicados). Deje filas vacías al final; el motor lee hasta la primera fila sin ID.
C3: Face total | D3: =SUM(D6:D405) -> 450.0005 | F3: Vidas | G3: =COUNT(A6:A405) -> 300 | H3: LE ponderada | I3: =SUMPRODUCT(Q6:Q305,D6:D305)/D3 -> 7.5267385 | J3: Mayor póliza % | K3: =MAX(R6:R305) -> 0.010170433 | L3: LE más antigua (m) | M3: =MAX(K6:K305) -> 11 | N3: MR ajust. prom. | O3: =SUMPRODUCT(P6:P305,D6:D305)/D3 -> 1.7910853
A5: ID | B5: Edad | C5: Sexo | D5: Face (USD mm) | E5: Aseguradora ID | F5: FSR | G5: Prima anual (% face) | H5: Premium financed (1/0) | I5: MR proveedor 1 | J5: MR proveedor 2 | K5: Antigüedad LE (meses) | L5: Enfermedad principal | M5: MR combinado | N5: BAF | O5: AAF | P5: MR ajustado | Q5: LE ajustada (años) | R5: % del face
A6: 1 | B6: 83 | C6: M | D6: 2.8855 | E6: 3 | F6: =INDEX(Factores!$C$29:$C$36,MATCH(E6,Factores!$A$29:$A$36,0)) -> A | G6: 0.047 | H6: 0 | I6: 1 | J6: 1.25 | K6: 11 | L6: Múltiple | M6: =IF(Supuestos!$C$23=1,AVERAGE(I6:J6),MIN(I6:J6)) -> 1.125 | N6: =INDEX(IF(H6=1,Factores!$C$6:$C$9,Factores!$B$6:$B$9),MATCH(M6,Factores!$A$6:$A$9,1)) -> 0.95 | O6: =INDEX(Factores!$B$13:$B$16,MATCH(B6,Factores!$A$13:$A$16,1)) -> 0.95 | P6: =M6*N6*O6 -> 1.0153125 | Q6: =LE!B4 -> 8.6870665 | R6: =D6/$D$3 -> 0.0064122151
A7: 2 | B7: 84 | C7: M | D7: 1.8765 | E7: 5 | F7: =INDEX(Factores!$C$29:$C$36,MATCH(E7,Factores!$A$29:$A$36,0)) -> A- | G7: 0.0558 | H7: 0 | I7: 2.5 | J7: 4 | K7: 7 | L7: Sin deterioro mayor | M7: =IF(Supuestos!$C$23=1,AVERAGE(I7:J7),MIN(I7:J7)) -> 3.25 | N7: =INDEX(IF(H7=1,Factores!$C$6:$C$9,Factores!$B$6:$B$9),MATCH(M7,Factores!$A$6:$A$9,1)) -> 0.8 | O7: =INDEX(Factores!$B$13:$B$16,MATCH(B7,Factores!$A$13:$A$16,1)) -> 0.95 | P7: =M7*N7*O7 -> 2.47 | Q7: =LE!B5 -> 4.8953688 | R7: =D7/$D$3 -> 0.0041699954
A8: 3 | B8: 82 | C8: F | D8: 1.4234 | E8: 6 | F8: =INDEX(Factores!$C$29:$C$36,MATCH(E8,Factores!$A$29:$A$36,0)) -> A | G8: 0.0479 | H8: 1 | I8: 2 | J8: 3 | K8: 4 | L8: Neurológica | M8: =IF(Supuestos!$C$23=1,AVERAGE(I8:J8),MIN(I8:J8)) -> 2.5 | N8: =INDEX(IF(H8=1,Factores!$C$6:$C$9,Factores!$B$6:$B$9),MATCH(M8,Factores!$A$6:$A$9,1)) -> 0.82 | O8: =INDEX(Factores!$B$13:$B$16,MATCH(B8,Factores!$A$13:$A$16,1)) -> 0.95 | P8: =M8*N8*O8 -> 1.9475 | Q8: =LE!B6 -> 6.8701522 | R8: =D8/$D$3 -> 0.0031631076
A9: 4 | B9: 79 | C9: M | D9: 1.126 | E9: 1 | F9: =INDEX(Factores!$C$29:$C$36,MATCH(E9,Factores!$A$29:$A$36,0)) -> A+ | G9: 0.041 | H9: 0 | I9: 2.25 | J9: 2.25 | K9: 10 | L9: Múltiple | M9: =IF(Supuestos!$C$23=1,AVERAGE(I9:J9),MIN(I9:J9)) -> 2.25 | N9: =INDEX(IF(H9=1,Factores!$C$6:$C$9,Factores!$B$6:$B$9),MATCH(M9,Factores!$A$6:$A$9,1)) -> 0.88 | O9: =INDEX(Factores!$B$13:$B$16,MATCH(B9,Factores!$A$13:$A$16,1)) -> 0.95 | P9: =M9*N9*O9 -> 1.881 | Q9: =LE!B7 -> 8.8634763 | R9: =D9/$D$3 -> 0.0025022194
A10: 5 | B10: 81 | C10: F | D10: 1.0981 | E10: 7 | F10: =INDEX(Factores!$C$29:$C$36,MATCH(E10,Factores!$A$29:$A$36,0)) -> A+ | G10: 0.0405 | H10: 0 | I10: 1 | J10: 1.25 | K10: 9 | L10: Neurológica | M10: =IF(Supuestos!$C$23=1,AVERAGE(I10:J10),MIN(I10:J10)) -> 1.125 | N10: =INDEX(IF(H10=1,Factores!$C$6:$C$9,Factores!$B$6:$B$9),MATCH(M10,Factores!$A$6:$A$9,1)) -> 0.95 | O10: =INDEX(Factores!$B$13:$B$16,MATCH(B10,Factores!$A$13:$A$16,1)) -> 0.95 | P10: =M10*N10*O10 -> 1.0153125 | Q10: =LE!B8 -> 9.8554715 | R10: =D10/$D$3 -> 0.0024402195
A11: 6 | B11: 78 | C11: M | D11: 3.0059 | E11: 2 | F11: =INDEX(Factores!$C$29:$C$36,MATCH(E11,Factores!$A$29:$A$36,0)) -> A+ | G11: 0.0364 | H11: 0 | I11: 1.75 | J11: 1.75 | K11: 7 | L11: Pulmonar | M11: =IF(Supuestos!$C$23=1,AVERAGE(I11:J11),MIN(I11:J11)) -> 1.75 | N11: =INDEX(IF(H11=1,Factores!$C$6:$C$9,Factores!$B$6:$B$9),MATCH(M11,Factores!$A$6:$A$9,1)) -> 0.88 | O11: =INDEX(Factores!$B$13:$B$16,MATCH(B11,Factores!$A$13:$A$16,1)) -> 0.95 | P11: =M11*N11*O11 -> 1.463 | Q11: =LE!B9 -> 10.543546 | R11: =D11/$D$3 -> 0.0066797704
A12: 7 | B12: 83 | C12: M | D12: 1.8356 | E12: 2 | F12: =INDEX(Factores!$C$29:$C$36,MATCH(E12,Factores!$A$29:$A$36,0)) -> A+ | G12: 0.0524 | H12: 0 | I12: 1.5 | J12: 1.5 | K12: 5 | L12: Cardiovascular | M12: =IF(Supuestos!$C$23=1,AVERAGE(I12:J12),MIN(I12:J12)) -> 1.5 | N12: =INDEX(IF(H12=1,Factores!$C$6:$C$9,Factores!$B$6:$B$9),MATCH(M12,Factores!$A$6:$A$9,1)) -> 0.88 | O12: =INDEX(Factores!$B$13:$B$16,MATCH(B12,Factores!$A$13:$A$16,1)) -> 0.95 | P12: =M12*N12*O12 -> 1.254 | Q12: =LE!B10 -> 7.97768 | R12: =D12/$D$3 -> 0.0040791066
A13: 8 | B13: 90 | C13: M | D13: 1.5065 | E13: 6 | F13: =INDEX(Factores!$C$29:$C$36,MATCH(E13,Factores!$A$29:$A$36,0)) -> A | G13: 0.0736 | H13: 1 | I13: 1.25 | J13: 1.75 | K13: 8 | L13: Múltiple | M13: =IF(Supuestos!$C$23=1,AVERAGE(I13:J13),MIN(I13:J13)) -> 1.5 | N13: =INDEX(IF(H13=1,Factores!$C$6:$C$9,Factores!$B$6:$B$9),MATCH(M13,Factores!$A$6:$A$9,1)) -> 0.82 | O13: =INDEX(Factores!$B$13:$B$16,MATCH(B13,Factores!$A$13:$A$16,1)) -> 1 | P13: =M13*N13*O13 -> 1.23 | Q13: =LE!B11 -> 4.7250665 | R13: =D13/$D$3 -> 0.0033477741
A14: 9 | B14: 81 | C14: F | D14: 1.2506 | E14: 7 | F14: =INDEX(Factores!$C$29:$C$36,MATCH(E14,Factores!$A$29:$A$36,0)) -> A+ | G14: 0.0515 | H14: 1 | I14: 1 | J14: 1 | K14: 10 | L14: Cardiovascular | M14: =IF(Supuestos!$C$23=1,AVERAGE(I14:J14),MIN(I14:J14)) -> 1 | N14: =INDEX(IF(H14=1,Factores!$C$6:$C$9,Factores!$B$6:$B$9),MATCH(M14,Factores!$A$6:$A$9,1)) -> 0.9 | O14: =INDEX(Factores!$B$13:$B$16,MATCH(B14,Factores!$A$13:$A$16,1)) -> 0.95 | P14: =M14*N14*O14 -> 0.855 | Q14: =LE!B12 -> 10.36828 | R14: =D14/$D$3 -> 0.002779108
A15: 10 | B15: 80 | C15: M | D15: 0.8872 | E15: 5 | F15: =INDEX(Factores!$C$29:$C$36,MATCH(E15,Factores!$A$29:$A$36,0)) -> A- | G15: 0.0447 | H15: 1 | I15: 1.75 | J15: 2.25 | K15: 6 | L15: Sin deterioro mayor | M15: =IF(Supuestos!$C$23=1,AVERAGE(I15:J15),MIN(I15:J15)) -> 2 | N15: =INDEX(IF(H15=1,Factores!$C$6:$C$9,Factores!$B$6:$B$9),MATCH(M15,Factores!$A$6:$A$9,1)) -> 0.82 | O15: =INDEX(Factores!$B$13:$B$16,MATCH(B15,Factores!$A$13:$A$16,1)) -> 0.95 | P15: =M15*N15*O15 -> 1.558 | Q15: =LE!B13 -> 8.9735149 | R15: =D15/$D$3 -> 0.0019715534
A16: 11 | B16: 85 | C16: M | D16: 1.418 | E16: 2 | F16: =INDEX(Factores!$C$29:$C$36,MATCH(E16,Factores!$A$29:$A$36,0)) -> A+ | G16: 0.0567 | H16: 1 | I16: 3 | J16: 3 | K16: 4 | L16: Cáncer | M16: =IF(Supuestos!$C$23=1,AVERAGE(I16:J16),MIN(I16:J16)) -> 3 | N16: =INDEX(IF(H16=1,Factores!$C$6:$C$9,Factores!$B$6:$B$9),MATCH(M16,Factores!$A$6:$A$9,1)) -> 0.74 | O16: =INDEX(Factores!$B$13:$B$16,MATCH(B16,Factores!$A$13:$A$16,1)) -> 1 | P16: =M16*N16*O16 -> 2.22 | Q16: =LE!B14 -> 4.8340514 | R16: =D16/$D$3 -> 0.0031511076
A17: 12 | B17: 85 | C17: F | D17: 2.1652 | E17: 3 | F17: =INDEX(Factores!$C$29:$C$36,MATCH(E17,Factores!$A$29:$A$36,0)) -> A | G17: 0.0542 | H17: 1 | I17: 2.25 | J17: 3 | K17: 4 | L17: Múltiple | M17: =IF(Supuestos!$C$23=1,AVERAGE(I17:J17),MIN(I17:J17)) -> 2.625 | N17: =INDEX(IF(H17=1,Factores!$C$6:$C$9,Factores!$B$6:$B$9),MATCH(M17,Factores!$A$6:$A$9,1)) -> 0.82 | O17: =INDEX(Factores!$B$13:$B$16,MATCH(B17,Factores!$A$13:$A$16,1)) -> 1 | P17: =M17*N17*O17 -> 2.1525 | Q17: =LE!B15 -> 4.946883 | R17: =D17/$D$3 -> 0.0048115502
... A305: 300 | B305: 83 | C305: M | D305: 0.9307 | E305: 1 | F305: =INDEX(Factores!$C$29:$C$36,MATCH(E305,Factores!$A$29:$A$36,0)) -> A+ | G305: 0.0517 | H305: 1 | I305: 1.25 | J305: 1.5 | K305: 3 | L305: Múltiple | M305: =IF(Supuestos!$C$23=1,AVERAGE(I305:J305),MIN(I305:J305)) -> 1.375 | N305: =INDEX(IF(H305=1,Factores!$C$6:$C$9,Factores!$B$6:$B$9),MATCH(M305,Factores!$A$6:$A$9,1)) -> 0.9 | O305: =INDEX(Factores!$B$13:$B$16,MATCH(B305,Factores!$A$13:$A$16,1)) -> 0.95 | P305: =M305*N305*O305 -> 1.175625 | Q305: =LE!B303 -> 8.201687 | R305: =D305/$D$3 -> 0.0020682199

Sheet LE
A1: Supervivencia ajustada por póliza: q_t = MIN(1, q_base(edad+t−1) × [1+(MRaj−1)·máx(0,1−(t−1)/W)] × (1−MI)^(t−1)); LE = Σ S_t + 0.5
A3: ID | B3: LE (años) | C3: 1 | D3: 2 | E3: 3 | F3: 4 | G3: 5 | H3: 6 | I3: 7 | J3: 8 | K3: 9 | L3: 10 | M3: 11 | N3: 12 | O3: 13 | P3: 14 | Q3: 15 | R3: 16 | S3: 17 | T3: 18 | U3: 19 | V3: 20 | W3: 21 | X3: 22 | Y3: 23 | Z3: 24 | AA3: 25 | AB3: 26 | AC3: 27 | AD3: 28 | AE3: 29 | AF3: 30 | AG3: 31 | AH3: 32 | AI3: 33 | AJ3: 34 | AK3: 35 | AL3: 36 | AM3: 37 | AN3: 38 | AO3: 39 | AP3: 40 | AQ3: 41 | AR3: 42 | AS3: 43 | AT3: 44 | AU3: 45
A4: =Cartera_Polizas!A6 -> 1 | B4: =SUM(C4:AU4)+0.5 -> 8.6870665 | C4: =1-MIN(1,INDEX(Tabla_Mortalidad!$B$5:$B$75,MIN(71,Cartera_Polizas!$B$6+0-49))*(1+(Cartera_Polizas!$P$6-1)*MAX(0,1-0/Supuestos!$C$20))*(1-Supuestos!$C$18)^0) -> 0.94453551 | D4: =C4*(1-MIN(1,INDEX(Tabla_Mortalidad!$B$5:$B$75,MIN(71,Cartera_Polizas!$B$6+1-49))*(1+(Cartera_Polizas!$P$6-1)*MAX(0,1-1/Supuestos!$C$20))*(1-Supuestos!$C$18)^1)) -> 0.88659446 | E4: =D4*(1-MIN(1,INDEX(Tabla_Mortalidad!$B$5:$B$75,MIN(71,Cartera_Polizas!$B$6+2-49))*(1+(Cartera_Polizas!$P$6-1)*MAX(0,1-2/Supuestos!$C$20))*(1-Supuestos!$C$18)^2)) -> 0.82646574 | F4: =E4*(1-MIN(1,INDEX(Tabla_Mortalidad!$B$5:$B$75,MIN(71,Cartera_Polizas!$B$6+3-49))*(1+(Cartera_Polizas!$P$6-1)*MAX(0,1-3/Supuestos!$C$20))*(1-Supuestos!$C$18)^3)) -> 0.76452198 | G4: =F4*(1-MIN(1,INDEX(Tabla_Mortalidad!$B$5:$B$75,MIN(71,Cartera_Polizas!$B$6+4-49))*(1+(Cartera_Polizas!$P$6-1)*MAX(0,1-4/Supuestos!$C$20))*(1-Supuestos!$C$18)^4)) -> 0.70122702 | H4: =G4*(1-MIN(1,INDEX(Tabla_Mortalidad!$B$5:$B$75,MIN(71,Cartera_Polizas!$B$6+5-49))*(1+(Cartera_Polizas!$P$6-1)*MAX(0,1-5/Supuestos!$C$20))*(1-Supuestos!$C$18)^5)) -> 0.63713115 | I4: =H4*(1-MIN(1,INDEX(Tabla_Mortalidad!$B$5:$B$75,MIN(71,Cartera_Polizas!$B$6+6-49))*(1+(Cartera_Polizas!$P$6-1)*MAX(0,1-6/Supuestos!$C$20))*(1-Supuestos!$C$18)^6)) -> 0.57287149 | J4: =I4*(1-MIN(1,INDEX(Tabla_Mortalidad!$B$5:$B$75,MIN(71,Cartera_Polizas!$B$6+7-49))*(1+(Cartera_Polizas!$P$6-1)*MAX(0,1-7/Supuestos!$C$20))*(1-Supuestos!$C$18)^7)) -> 0.50915818 | K4: =J4*(1-MIN(1,INDEX(Tabla_Mortalidad!$B$5:$B$75,MIN(71,Cartera_Polizas!$B$6+8-49))*(1+(Cartera_Polizas!$P$6-1)*MAX(0,1-8/Supuestos!$C$20))*(1-Supuestos!$C$18)^8)) -> 0.44675842 | L4: =K4*(1-MIN(1,INDEX(Tabla_Mortalidad!$B$5:$B$75,MIN(71,Cartera_Polizas!$B$6+9-49))*(1+(Cartera_Polizas!$P$6-1)*MAX(0,1-9/Supuestos!$C$20))*(1-Supuestos!$C$18)^9)) -> 0.38647179 | M4: =L4*(1-MIN(1,INDEX(Tabla_Mortalidad!$B$5:$B$75,MIN(71,Cartera_Polizas!$B$6+10-49))*(1+(Cartera_Polizas!$P$6-1)*MAX(0,1-10/Supuestos!$C$20))*(1-Supuestos!$C$18)^10)) -> 0.329099 | N4: =M4*(1-MIN(1,INDEX(Tabla_Mortalidad!$B$5:$B$75,MIN(71,Cartera_Polizas!$B$6+11-49))*(1+(Cartera_Polizas!$P$6-1)*MAX(0,1-11/Supuestos!$C$20))*(1-Supuestos!$C$18)^11)) -> 0.27540408 | O4: =N4*(1-MIN(1,INDEX(Tabla_Mortalidad!$B$5:$B$75,MIN(71,Cartera_Polizas!$B$6+12-49))*(1+(Cartera_Polizas!$P$6-1)*MAX(0,1-12/Supuestos!$C$20))*(1-Supuestos!$C$18)^12)) -> 0.22607163 | P4: =O4*(1-MIN(1,INDEX(Tabla_Mortalidad!$B$5:$B$75,MIN(71,Cartera_Polizas!$B$6+13-49))*(1+(Cartera_Polizas!$P$6-1)*MAX(0,1-13/Supuestos!$C$20))*(1-Supuestos!$C$18)^13)) -> 0.18166481 | Q4: =P4*(1-MIN(1,INDEX(Tabla_Mortalidad!$B$5:$B$75,MIN(71,Cartera_Polizas!$B$6+14-49))*(1+(Cartera_Polizas!$P$6-1)*MAX(0,1-14/Supuestos!$C$20))*(1-Supuestos!$C$18)^14)) -> 0.14258578 | R4: =Q4*(1-MIN(1,INDEX(Tabla_Mortalidad!$B$5:$B$75,MIN(71,Cartera_Polizas!$B$6+15-49))*(1+(Cartera_Polizas!$P$6-1)*MAX(0,1-15/Supuestos!$C$20))*(1-Supuestos!$C$18)^15)) -> 0.10904366 | S4: =R4*(1-MIN(1,INDEX(Tabla_Mortalidad!$B$5:$B$75,MIN(71,Cartera_Polizas!$B$6+16-49))*(1+(Cartera_Polizas!$P$6-1)*MAX(0,1-16/Supuestos!$C$20))*(1-Supuestos!$C$18)^16)) -> 0.081008334 | T4: =S4*(1-MIN(1,INDEX(Tabla_Mortalidad!$B$5:$B$75,MIN(71,Cartera_Polizas!$B$6+17-49))*(1+(Cartera_Polizas!$P$6-1)*MAX(0,1-17/Supuestos!$C$20))*(1-Supuestos!$C$18)^17)) -> 0.058285664 | U4: =T4*(1-MIN(1,INDEX(Tabla_Mortalidad!$B$5:$B$75,MIN(71,Cartera_Polizas!$B$6+18-49))*(1+(Cartera_Polizas!$P$6-1)*MAX(0,1-18/Supuestos!$C$20))*(1-Supuestos!$C$18)^18)) -> 0.040483426 | V4: =U4*(1-MIN(1,INDEX(Tabla_Mortalidad!$B$5:$B$75,MIN(71,Cartera_Polizas!$B$6+19-49))*(1+(Cartera_Polizas!$P$6-1)*MAX(0,1-19/Supuestos!$C$20))*(1-Supuestos!$C$18)^19)) -> 0.027048146 | W4: =V4*(1-MIN(1,INDEX(Tabla_Mortalidad!$B$5:$B$75,MIN(71,Cartera_Polizas!$B$6+20-49))*(1+(Cartera_Polizas!$P$6-1)*MAX(0,1-20/Supuestos!$C$20))*(1-Supuestos!$C$18)^20)) -> 0.01731733 | X4: =W4*(1-MIN(1,INDEX(Tabla_Mortalidad!$B$5:$B$75,MIN(71,Cartera_Polizas!$B$6+21-49))*(1+(Cartera_Polizas!$P$6-1)*MAX(0,1-21/Supuestos!$C$20))*(1-Supuestos!$C$18)^21)) -> 0.010580955 | Y4: =X4*(1-MIN(1,INDEX(Tabla_Mortalidad!$B$5:$B$75,MIN(71,Cartera_Polizas!$B$6+22-49))*(1+(Cartera_Polizas!$P$6-1)*MAX(0,1-22/Supuestos!$C$20))*(1-Supuestos!$C$18)^22)) -> 0.0061428874 | Z4: =Y4*(1-MIN(1,INDEX(Tabla_Mortalidad!$B$5:$B$75,MIN(71,Cartera_Polizas!$B$6+23-49))*(1+(Cartera_Polizas!$P$6-1)*MAX(0,1-23/Supuestos!$C$20))*(1-Supuestos!$C$18)^23)) -> 0.0033730796 | AA4: =Z4*(1-MIN(1,INDEX(Tabla_Mortalidad!$B$5:$B$75,MIN(71,Cartera_Polizas!$B$6+24-49))*(1+(Cartera_Polizas!$P$6-1)*MAX(0,1-24/Supuestos!$C$20))*(1-Supuestos!$C$18)^24)) -> 0.0017434572 | AB4: =AA4*(1-MIN(1,INDEX(Tabla_Mortalidad!$B$5:$B$75,MIN(71,Cartera_Polizas!$B$6+25-49))*(1+(Cartera_Polizas!$P$6-1)*MAX(0,1-25/Supuestos!$C$20))*(1-Supuestos!$C$18)^25)) -> 0.00084412856 | AC4: =AB4*(1-MIN(1,INDEX(Tabla_Mortalidad!$B$5:$B$75,MIN(71,Cartera_Polizas!$B$6+26-49))*(1+(Cartera_Polizas!$P$6-1)*MAX(0,1-26/Supuestos!$C$20))*(1-Supuestos!$C$18)^26)) -> 0.00038098703 | AD4: =AC4*(1-MIN(1,INDEX(Tabla_Mortalidad!$B$5:$B$75,MIN(71,Cartera_Polizas!$B$6+27-49))*(1+(Cartera_Polizas!$P$6-1)*MAX(0,1-27/Supuestos!$C$20))*(1-Supuestos!$C$18)^27)) -> 0.00015954907 | AE4: =AD4*(1-MIN(1,INDEX(Tabla_Mortalidad!$B$5:$B$75,MIN(71,Cartera_Polizas!$B$6+28-49))*(1+(Cartera_Polizas!$P$6-1)*MAX(0,1-28/Supuestos!$C$20))*(1-Supuestos!$C$18)^28)) -> 6.1733775e-05 | AF4: =AE4*(1-MIN(1,INDEX(Tabla_Mortalidad!$B$5:$B$75,MIN(71,Cartera_Polizas!$B$6+29-49))*(1+(Cartera_Polizas!$P$6-1)*MAX(0,1-29/Supuestos!$C$20))*(1-Supuestos!$C$18)^29)) -> 2.1992455e-05 | AG4: =AF4*(1-MIN(1,INDEX(Tabla_Mortalidad!$B$5:$B$75,MIN(71,Cartera_Polizas!$B$6+30-49))*(1+(Cartera_Polizas!$P$6-1)*MAX(0,1-30/Supuestos!$C$20))*(1-Supuestos!$C$18)^30)) -> 7.1962007e-06 | AH4: =AG4*(1-MIN(1,INDEX(Tabla_Mortalidad!$B$5:$B$75,MIN(71,Cartera_Polizas!$B$6+31-49))*(1+(Cartera_Polizas!$P$6-1)*MAX(0,1-31/Supuestos!$C$20))*(1-Supuestos!$C$18)^31)) -> 2.1608773e-06 | AI4: =AH4*(1-MIN(1,INDEX(Tabla_Mortalidad!$B$5:$B$75,MIN(71,Cartera_Polizas!$B$6+32-49))*(1+(Cartera_Polizas!$P$6-1)*MAX(0,1-32/Supuestos!$C$20))*(1-Supuestos!$C$18)^32)) -> 5.9612222e-07 | AJ4: =AI4*(1-MIN(1,INDEX(Tabla_Mortalidad!$B$5:$B$75,MIN(71,Cartera_Polizas!$B$6+33-49))*(1+(Cartera_Polizas!$P$6-1)*MAX(0,1-33/Supuestos!$C$20))*(1-Supuestos!$C$18)^33)) -> 1.5161486e-07 | AK4: =AJ4*(1-MIN(1,INDEX(Tabla_Mortalidad!$B$5:$B$75,MIN(71,Cartera_Polizas!$B$6+34-49))*(1+(Cartera_Polizas!$P$6-1)*MAX(0,1-34/Supuestos!$C$20))*(1-Supuestos!$C$18)^34)) -> 3.5770513e-08 | AL4: =AK4*(1-MIN(1,INDEX(Tabla_Mortalidad!$B$5:$B$75,MIN(71,Cartera_Polizas!$B$6+35-49))*(1+(Cartera_Polizas!$P$6-1)*MAX(0,1-35/Supuestos!$C$20))*(1-Supuestos!$C$18)^35)) -> 7.897997e-09 | AM4: =AL4*(1-MIN(1,INDEX(Tabla_Mortalidad!$B$5:$B$75,MIN(71,Cartera_Polizas!$B$6+36-49))*(1+(Cartera_Polizas!$P$6-1)*MAX(0,1-36/Supuestos!$C$20))*(1-Supuestos!$C$18)^36)) -> 1.6502238e-09 | AN4: =AM4*(1-MIN(1,INDEX(Tabla_Mortalidad!$B$5:$B$75,MIN(71,Cartera_Polizas!$B$6+37-49))*(1+(Cartera_Polizas!$P$6-1)*MAX(0,1-37/Supuestos!$C$20))*(1-Supuestos!$C$18)^37)) -> 2.7935203e-10 | AO4: =AN4*(1-MIN(1,INDEX(Tabla_Mortalidad!$B$5:$B$75,MIN(71,Cartera_Polizas!$B$6+38-49))*(1+(Cartera_Polizas!$P$6-1)*MAX(0,1-38/Supuestos!$C$20))*(1-Supuestos!$C$18)^38)) -> 4.8449389e-11 | AP4: =AO4*(1-MIN(1,INDEX(Tabla_Mortalidad!$B$5:$B$75,MIN(71,Cartera_Polizas!$B$6+39-49))*(1+(Cartera_Polizas!$P$6-1)*MAX(0,1-39/Supuestos!$C$20))*(1-Supuestos!$C$18)^39)) -> 8.6030474e-12 | AQ4: =AP4*(1-MIN(1,INDEX(Tabla_Mortalidad!$B$5:$B$75,MIN(71,Cartera_Polizas!$B$6+40-49))*(1+(Cartera_Polizas!$P$6-1)*MAX(0,1-40/Supuestos!$C$20))*(1-Supuestos!$C$18)^40)) -> 1.5630006e-12 | AR4: =AQ4*(1-MIN(1,INDEX(Tabla_Mortalidad!$B$5:$B$75,MIN(71,Cartera_Polizas!$B$6+41-49))*(1+(Cartera_Polizas!$P$6-1)*MAX(0,1-41/Supuestos!$C$20))*(1-Supuestos!$C$18)^41)) -> 2.9036094e-13 | AS4: =AR4*(1-MIN(1,INDEX(Tabla_Mortalidad!$B$5:$B$75,MIN(71,Cartera_Polizas!$B$6+42-49))*(1+(Cartera_Polizas!$P$6-1)*MAX(0,1-42/Supuestos!$C$20))*(1-Supuestos!$C$18)^42)) -> 5.5122881e-14 | AT4: =AS4*(1-MIN(1,INDEX(Tabla_Mortalidad!$B$5:$B$75,MIN(71,Cartera_Polizas!$B$6+43-49))*(1+(Cartera_Polizas!$P$6-1)*MAX(0,1-43/Supuestos!$C$20))*(1-Supuestos!$C$18)^43)) -> 1.0687963e-14 | AU4: =AT4*(1-MIN(1,INDEX(Tabla_Mortalidad!$B$5:$B$75,MIN(71,Cartera_Polizas!$B$6+44-49))*(1+(Cartera_Polizas!$P$6-1)*MAX(0,1-44/Supuestos!$C$20))*(1-Supuestos!$C$18)^44)) -> 2.1154038e-15
A5: =Cartera_Polizas!A7 -> 2 | B5: =SUM(C5:AU5)+0.5 -> 4.8953688 | C5: =1-MIN(1,INDEX(Tabla_Mortalidad!$B$5:$B$75,MIN(71,Cartera_Polizas!$B$7+0-49))*(1+(Cartera_Polizas!$P$7-1)*MAX(0,1-0/Supuestos!$C$20))*(1-Supuestos!$C$18)^0) -> 0.84986599 | D5: =C5*(1-MIN(1,INDEX(Tabla_Mortalidad!$B$5:$B$75,MIN(71,Cartera_Polizas!$B$7+1-49))*(1+(Cartera_Polizas!$P$7-1)*MAX(0,1-1/Supuestos!$C$20))*(1-Supuestos!$C$18)^1)) -> 0.71426169 | E5: =D5*(1-MIN(1,INDEX(Tabla_Mortalidad!$B$5:$B$75,MIN(71,Cartera_Polizas!$B$7+2-49))*(1+(Cartera_Polizas!$P$7-1)*MAX(0,1-2/Supuestos!$C$20))*(1-Supuestos!$C$18)^2)) -> 0.59339416 | F5: =E5*(1-MIN(1,INDEX(Tabla_Mortalidad!$B$5:$B$75,MIN(71,Cartera_Polizas!$B$7+3-49))*(1+(Cartera_Polizas!$P$7-1)*MAX(0,1-3/Supuestos!$C$20))*(1-Supuestos!$C$18)^3)) -> 0.48714912 | G5: =F5*(1-MIN(1,INDEX(Tabla_Mortalidad!$B$5:$B$75,MIN(71,Cartera_Polizas!$B$7+4-49))*(1+(Cartera_Polizas!$P$7-1)*MAX(0,1-4/Supuestos!$C$20))*(1-Supuestos!$C$18)^4)) -> 0.39509467 | H5: =G5*(1-MIN(1,INDEX(Tabla_Mortalidad!$B$5:$B$75,MIN(71,Cartera_Polizas!$B$7+5-49))*(1+(Cartera_Polizas!$P$7-1)*MAX(0,1-5/Supuestos!$C$20))*(1-Supuestos!$C$18)^5)) -> 0.31652027 | I5: =H5*(1-MIN(1,INDEX(Tabla_Mortalidad!$B$5:$B$75,MIN(71,Cartera_Polizas!$B$7+6-49))*(1+(Cartera_Polizas!$P$7-1)*MAX(0,1-6/Supuestos!$C$20))*(1-Supuestos!$C$18)^6)) -> 0.25047547 | J5: =I5*(1-MIN(1,INDEX(Tabla_Mortalidad!$B$5:$B$75,MIN(71,Cartera_Polizas!$B$7+7-49))*(1+(Cartera_Polizas!$P$7-1)*MAX(0,1-7/Supuestos!$C$20))*(1-Supuestos!$C$18)^7)) -> 0.1958274 | K5: =J5*(1-MIN(1,INDEX(Tabla_Mortalidad!$B$5:$B$75,MIN(71,Cartera_Polizas!$B$7+8-49))*(1+(Cartera_Polizas!$P$7-1)*MAX(0,1-8/Supuestos!$C$20))*(1-Supuestos!$C$18)^8)) -> 0.15132286 | L5: =K5*(1-MIN(1,INDEX(Tabla_Mortalidad!$B$5:$B$75,MIN(71,Cartera_Polizas!$B$7+9-49))*(1+(Cartera_Polizas!$P$7-1)*MAX(0,1-9/Supuestos!$C$20))*(1-Supuestos!$C$18)^9)) -> 0.11565237 | M5: =L5*(1-MIN(1,INDEX(Tabla_Mortalidad!$B$5:$B$75,MIN(71,Cartera_Polizas!$B$7+10-49))*(1+(Cartera_Polizas!$P$7-1)*MAX(0,1-10/Supuestos!$C$20))*(1-Supuestos!$C$18)^10)) -> 0.087510399 | N5: =M5*(1-MIN(1,INDEX(Tabla_Mortalidad!$B$5:$B$75,MIN(71,Cartera_Polizas!$B$7+11-49))*(1+(Cartera_Polizas!$P$7-1)*MAX(0,1-11/Supuestos!$C$20))*(1-Supuestos!$C$18)^11)) -> 0.065647376 | O5: =N5*(1-MIN(1,INDEX(Tabla_Mortalidad!$B$5:$B$75,MIN(71,Cartera_Polizas!$B$7+12-49))*(1+(Cartera_Polizas!$P$7-1)*MAX(0,1-12/Supuestos!$C$20))*(1-Supuestos!$C$18)^12)) -> 0.048911581 | P5: =O5*(1-MIN(1,INDEX(Tabla_Mortalidad!$B$5:$B$75,MIN(71,Cartera_Polizas!$B$7+13-49))*(1+(Cartera_Polizas!$P$7-1)*MAX(0,1-13/Supuestos!$C$20))*(1-Supuestos!$C$18)^13)) -> 0.036277326 | Q5: =P5*(1-MIN(1,INDEX(Tabla_Mortalidad!$B$5:$B$75,MIN(71,Cartera_Polizas!$B$7+14-49))*(1+(Cartera_Polizas!$P$7-1)*MAX(0,1-14/Supuestos!$C$20))*(1-Supuestos!$C$18)^14)) -> 0.026859973 | R5: =Q5*(1-MIN(1,INDEX(Tabla_Mortalidad!$B$5:$B$75,MIN(71,Cartera_Polizas!$B$7+15-49))*(1+(Cartera_Polizas!$P$7-1)*MAX(0,1-15/Supuestos!$C$20))*(1-Supuestos!$C$18)^15)) -> 0.019919522 | S5: =R5*(1-MIN(1,INDEX(Tabla_Mortalidad!$B$5:$B$75,MIN(71,Cartera_Polizas!$B$7+16-49))*(1+(Cartera_Polizas!$P$7-1)*MAX(0,1-16/Supuestos!$C$20))*(1-Supuestos!$C$18)^16)) -> 0.01430406 | T5: =S5*(1-MIN(1,INDEX(Tabla_Mortalidad!$B$5:$B$75,MIN(71,Cartera_Polizas!$B$7+17-49))*(1+(Cartera_Polizas!$P$7-1)*MAX(0,1-17/Supuestos!$C$20))*(1-Supuestos!$C$18)^17)) -> 0.0099132052 | U5: =T5*(1-MIN(1,INDEX(Tabla_Mortalidad!$B$5:$B$75,MIN(71,Cartera_Polizas!$B$7+18-49))*(1+(Cartera_Polizas!$P$7-1)*MAX(0,1-18/Supuestos!$C$20))*(1-Supuestos!$C$18)^18)) -> 0.0066067664 | V5: =U5*(1-MIN(1,INDEX(Tabla_Mortalidad!$B$5:$B$75,MIN(71,Cartera_Polizas!$B$7+19-49))*(1+(Cartera_Polizas!$P$7-1)*MAX(0,1-19/Supuestos!$C$20))*(1-Supuestos!$C$18)^19)) -> 0.0042179783 | W5: =V5*(1-MIN(1,INDEX(Tabla_Mortalidad!$B$5:$B$75,MIN(71,Cartera_Polizas!$B$7+20-49))*(1+(Cartera_Polizas!$P$7-1)*MAX(0,1-20/Supuestos!$C$20))*(1-Supuestos!$C$18)^20)) -> 0.0025689558 | X5: =W5*(1-MIN(1,INDEX(Tabla_Mortalidad!$B$5:$B$75,MIN(71,Cartera_Polizas!$B$7+21-49))*(1+(Cartera_Polizas!$P$7-1)*MAX(0,1-21/Supuestos!$C$20))*(1-Supuestos!$C$18)^21)) -> 0.0014860203 | Y5: =X5*(1-MIN(1,INDEX(Tabla_Mortalidad!$B$5:$B$75,MIN(71,Cartera_Polizas!$B$7+22-49))*(1+(Cartera_Polizas!$P$7-1)*MAX(0,1-22/Supuestos!$C$20))*(1-Supuestos!$C$18)^22)) -> 0.00081261157 | Z5: =Y5*(1-MIN(1,INDEX(Tabla_Mortalidad!$B$5:$B$75,MIN(71,Cartera_Polizas!$B$7+23-49))*(1+(Cartera_Polizas!$P$7-1)*MAX(0,1-23/Supuestos!$C$20))*(1-Supuestos!$C$18)^23)) -> 0.00041804498 | AA5: =Z5*(1-MIN(1,INDEX(Tabla_Mortalidad!$B$5:$B$75,MIN(71,Cartera_Polizas!$B$7+24-49))*(1+(Cartera_Polizas!$P$7-1)*MAX(0,1-24/Supuestos!$C$20))*(1-Supuestos!$C$18)^24)) -> 0.00020132095 | AB5: =AA5*(1-MIN(1,INDEX(Tabla_Mortalidad!$B$5:$B$75,MIN(71,Cartera_Polizas!$B$7+25-49))*(1+(Cartera_Polizas!$P$7-1)*MAX(0,1-25/Supuestos!$C$20))*(1-Supuestos!$C$18)^25)) -> 9.0308669e-05 | AC5: =AB5*(1-MIN(1,INDEX(Tabla_Mortalidad!$B$5:$B$75,MIN(71,Cartera_Polizas!$B$7+26-49))*(1+(Cartera_Polizas!$P$7-1)*MAX(0,1-26/Supuestos!$C$20))*(1-Supuestos!$C$18)^26)) -> 3.7555539e-05 | AD5: =AC5*(1-MIN(1,INDEX(Tabla_Mortalidad!$B$5:$B$75,MIN(71,Cartera_Polizas!$B$7+27-49))*(1+(Cartera_Polizas!$P$7-1)*MAX(0,1-27/Supuestos!$C$20))*(1-Supuestos!$C$18)^27)) -> 1.4415536e-05 | AE5: =AD5*(1-MIN(1,INDEX(Tabla_Mortalidad!$B$5:$B$75,MIN(71,Cartera_Polizas!$B$7+28-49))*(1+(Cartera_Polizas!$P$7-1)*MAX(0,1-28/Supuestos!$C$20))*(1-Supuestos!$C$18)^28)) -> 5.0888538e-06 | AF5: =AE5*(1-MIN(1,INDEX(Tabla_Mortalidad!$B$5:$B$75,MIN(71,Cartera_Polizas!$B$7+29-49))*(1+(Cartera_Polizas!$P$7-1)*MAX(0,1-29/Supuestos!$C$20))*(1-Supuestos!$C$18)^29)) -> 1.6479307e-06 | AG5: =AF5*(1-MIN(1,INDEX(Tabla_Mortalidad!$B$5:$B$75,MIN(71,Cartera_Polizas!$B$7+30-49))*(1+(Cartera_Polizas!$P$7-1)*MAX(0,1-30/Supuestos!$C$20))*(1-Supuestos!$C$18)^30)) -> 4.8904671e-07 | AH5: =AG5*(1-MIN(1,INDEX(Tabla_Mortalidad!$B$5:$B$75,MIN(71,Cartera_Polizas!$B$7+31-49))*(1+(Cartera_Polizas!$P$7-1)*MAX(0,1-31/Supuestos!$C$20))*(1-Supuestos!$C$18)^31)) -> 1.3313398e-07 | AI5: =AH5*(1-MIN(1,INDEX(Tabla_Mortalidad!$B$5:$B$75,MIN(71,Cartera_Polizas!$B$7+32-49))*(1+(Cartera_Polizas!$P$7-1)*MAX(0,1-32/Supuestos!$C$20))*(1-Supuestos!$C$18)^32)) -> 3.3361795e-08 | AJ5: =AI5*(1-MIN(1,INDEX(Tabla_Mortalidad!$B$5:$B$75,MIN(71,Cartera_Polizas!$B$7+33-49))*(1+(Cartera_Polizas!$P$7-1)*MAX(0,1-33/Supuestos!$C$20))*(1-Supuestos!$C$18)^33)) -> 7.7429583e-09 | AK5: =AJ5*(1-MIN(1,INDEX(Tabla_Mortalidad!$B$5:$B$75,MIN(71,Cartera_Polizas!$B$7+34-49))*(1+(Cartera_Polizas!$P$7-1)*MAX(0,1-34/Supuestos!$C$20))*(1-Supuestos!$C$18)^34)) -> 1.6792983e-09 | AL5: =AK5*(1-MIN(1,INDEX(Tabla_Mortalidad!$B$5:$B$75,MIN(71,Cartera_Polizas!$B$7+35-49))*(1+(Cartera_Polizas!$P$7-1)*MAX(0,1-35/Supuestos!$C$20))*(1-Supuestos!$C$18)^35)) -> 3.4420056e-10 | AM5: =AL5*(1-MIN(1,INDEX(Tabla_Mortalidad!$B$5:$B$75,MIN(71,Cartera_Polizas!$B$7+36-49))*(1+(Cartera_Polizas!$P$7-1)*MAX(0,1-36/Supuestos!$C$20))*(1-Supuestos!$C$18)^36)) -> 5.6829864e-11 | AN5: =AM5*(1-MIN(1,INDEX(Tabla_Mortalidad!$B$5:$B$75,MIN(71,Cartera_Polizas!$B$7+37-49))*(1+(Cartera_Polizas!$P$7-1)*MAX(0,1-37/Supuestos!$C$20))*(1-Supuestos!$C$18)^37)) -> 9.6202332e-12 | AO5: =AN5*(1-MIN(1,INDEX(Tabla_Mortalidad!$B$5:$B$75,MIN(71,Cartera_Polizas!$B$7+38-49))*(1+(Cartera_Polizas!$P$7-1)*MAX(0,1-38/Supuestos!$C$20))*(1-Supuestos!$C$18)^38)) -> 1.6684841e-12 | AP5: =AO5*(1-MIN(1,INDEX(Tabla_Mortalidad!$B$5:$B$75,MIN(71,Cartera_Polizas!$B$7+39-49))*(1+(Cartera_Polizas!$P$7-1)*MAX(0,1-39/Supuestos!$C$20))*(1-Supuestos!$C$18)^39)) -> 2.9626891e-13 | AQ5: =AP5*(1-MIN(1,INDEX(Tabla_Mortalidad!$B$5:$B$75,MIN(71,Cartera_Polizas!$B$7+40-49))*(1+(Cartera_Polizas!$P$7-1)*MAX(0,1-40/Supuestos!$C$20))*(1-Supuestos!$C$18)^40)) -> 5.3826101e-14 | AR5: =AQ5*(1-MIN(1,INDEX(Tabla_Mortalidad!$B$5:$B$75,MIN(71,Cartera_Polizas!$B$7+41-49))*(1+(Cartera_Polizas!$P$7-1)*MAX(0,1-41/Supuestos!$C$20))*(1-Supuestos!$C$18)^41)) -> 9.9993543e-15 | AS5: =AR5*(1-MIN(1,INDEX(Tabla_Mortalidad!$B$5:$B$75,MIN(71,Cartera_Polizas!$B$7+42-49))*(1+(Cartera_Polizas!$P$7-1)*MAX(0,1-42/Supuestos!$C$20))*(1-Supuestos!$C$18)^42)) -> 1.8983036e-15 | AT5: =AS5*(1-MIN(1,INDEX(Tabla_Mortalidad!$B$5:$B$75,MIN(71,Cartera_Polizas!$B$7+43-49))*(1+(Cartera_Polizas!$P$7-1)*MAX(0,1-43/Supuestos!$C$20))*(1-Supuestos!$C$18)^43)) -> 3.6806857e-16 | AU5: =AT5*(1-MIN(1,INDEX(Tabla_Mortalidad!$B$5:$B$75,MIN(71,Cartera_Polizas!$B$7+44-49))*(1+(Cartera_Polizas!$P$7-1)*MAX(0,1-44/Supuestos!$C$20))*(1-Supuestos!$C$18)^44)) -> 7.2849581e-17
A6: =Cartera_Polizas!A8 -> 3 | B6: =SUM(C6:AU6)+0.5 -> 6.8701522 | C6: =1-MIN(1,INDEX(Tabla_Mortalidad!$B$5:$B$75,MIN(71,Cartera_Polizas!$B$8+0-49))*(1+(Cartera_Polizas!$P$8-1)*MAX(0,1-0/Supuestos!$C$20))*(1-Supuestos!$C$18)^0) -> 0.90441865 | D6: =C6*(1-MIN(1,INDEX(Tabla_Mortalidad!$B$5:$B$75,MIN(71,Cartera_Polizas!$B$8+1-49))*(1+(Cartera_Polizas!$P$8-1)*MAX(0,1-1/Supuestos!$C$20))*(1-Supuestos!$C$18)^1)) -> 0.81178567 | E6: =D6*(1-MIN(1,INDEX(Tabla_Mortalidad!$B$5:$B$75,MIN(71,Cartera_Polizas!$B$8+2-49))*(1+(Cartera_Polizas!$P$8-1)*MAX(0,1-2/Supuestos!$C$20))*(1-Supuestos!$C$18)^2)) -> 0.72282063 | F6: =E6*(1-MIN(1,INDEX(Tabla_Mortalidad!$B$5:$B$75,MIN(71,Cartera_Polizas!$B$8+3-49))*(1+(Cartera_Polizas!$P$8-1)*MAX(0,1-3/Supuestos!$C$20))*(1-Supuestos!$C$18)^3)) -> 0.63819462 | G6: =F6*(1-MIN(1,INDEX(Tabla_Mortalidad!$B$5:$B$75,MIN(71,Cartera_Polizas!$B$8+4-49))*(1+(Cartera_Polizas!$P$8-1)*MAX(0,1-4/Supuestos!$C$20))*(1-Supuestos!$C$18)^4)) -> 0.5585075 | H6: =G6*(1-MIN(1,INDEX(Tabla_Mortalidad!$B$5:$B$75,MIN(71,Cartera_Polizas!$B$8+5-49))*(1+(Cartera_Polizas!$P$8-1)*MAX(0,1-5/Supuestos!$C$20))*(1-Supuestos!$C$18)^5)) -> 0.48427174 | I6: =H6*(1-MIN(1,INDEX(Tabla_Mortalidad!$B$5:$B$75,MIN(71,Cartera_Polizas!$B$8+6-49))*(1+(Cartera_Polizas!$P$8-1)*MAX(0,1-6/Supuestos!$C$20))*(1-Supuestos!$C$18)^6)) -> 0.41588733 | J6: =I6*(1-MIN(1,INDEX(Tabla_Mortalidad!$B$5:$B$75,MIN(71,Cartera_Polizas!$B$8+7-49))*(1+(Cartera_Polizas!$P$8-1)*MAX(0,1-7/Supuestos!$C$20))*(1-Supuestos!$C$18)^7)) -> 0.35363305 | K6: =J6*(1-MIN(1,INDEX(Tabla_Mortalidad!$B$5:$B$75,MIN(71,Cartera_Polizas!$B$8+8-49))*(1+(Cartera_Polizas!$P$8-1)*MAX(0,1-8/Supuestos!$C$20))*(1-Supuestos!$C$18)^8)) -> 0.29765317 | L6: =K6*(1-MIN(1,INDEX(Tabla_Mortalidad!$B$5:$B$75,MIN(71,Cartera_Polizas!$B$8+9-49))*(1+(Cartera_Polizas!$P$8-1)*MAX(0,1-9/Supuestos!$C$20))*(1-Supuestos!$C$18)^9)) -> 0.24795554 | M6: =L6*(1-MIN(1,INDEX(Tabla_Mortalidad!$B$5:$B$75,MIN(71,Cartera_Polizas!$B$8+10-49))*(1+(Cartera_Polizas!$P$8-1)*MAX(0,1-10/Supuestos!$C$20))*(1-Supuestos!$C$18)^10)) -> 0.20441496 | N6: =M6*(1-MIN(1,INDEX(Tabla_Mortalidad!$B$5:$B$75,MIN(71,Cartera_Polizas!$B$8+11-49))*(1+(Cartera_Polizas!$P$8-1)*MAX(0,1-11/Supuestos!$C$20))*(1-Supuestos!$C$18)^11)) -> 0.16678374 | O6: =N6*(1-MIN(1,INDEX(Tabla_Mortalidad!$B$5:$B$75,MIN(71,Cartera_Polizas!$B$8+12-49))*(1+(Cartera_Polizas!$P$8-1)*MAX(0,1-12/Supuestos!$C$20))*(1-Supuestos!$C$18)^12)) -> 0.1347079 | P6: =O6*(1-MIN(1,INDEX(Tabla_Mortalidad!$B$5:$B$75,MIN(71,Cartera_Polizas!$B$8+13-49))*(1+(Cartera_Polizas!$P$8-1)*MAX(0,1-13/Supuestos!$C$20))*(1-Supuestos!$C$18)^13)) -> 0.10774805 | Q6: =P6*(1-MIN(1,INDEX(Tabla_Mortalidad!$B$5:$B$75,MIN(71,Cartera_Polizas!$B$8+14-49))*(1+(Cartera_Polizas!$P$8-1)*MAX(0,1-14/Supuestos!$C$20))*(1-Supuestos!$C$18)^14)) -> 0.085404525 | R6: =Q6*(1-MIN(1,INDEX(Tabla_Mortalidad!$B$5:$B$75,MIN(71,Cartera_Polizas!$B$8+15-49))*(1+(Cartera_Polizas!$P$8-1)*MAX(0,1-15/Supuestos!$C$20))*(1-Supuestos!$C$18)^15)) -> 0.067143136 | S6: =R6*(1-MIN(1,INDEX(Tabla_Mortalidad!$B$5:$B$75,MIN(71,Cartera_Polizas!$B$8+16-49))*(1+(Cartera_Polizas!$P$8-1)*MAX(0,1-16/Supuestos!$C$20))*(1-Supuestos!$C$18)^16)) -> 0.051427245 | T6: =S6*(1-MIN(1,INDEX(Tabla_Mortalidad!$B$5:$B$75,MIN(71,Cartera_Polizas!$B$8+17-49))*(1+(Cartera_Polizas!$P$8-1)*MAX(0,1-17/Supuestos!$C$20))*(1-Supuestos!$C$18)^17)) -> 0.038271316 | U6: =T6*(1-MIN(1,INDEX(Tabla_Mortalidad!$B$5:$B$75,MIN(71,Cartera_Polizas!$B$8+18-49))*(1+(Cartera_Polizas!$P$8-1)*MAX(0,1-18/Supuestos!$C$20))*(1-Supuestos!$C$18)^18)) -> 0.027589966 | V6: =U6*(1-MIN(1,INDEX(Tabla_Mortalidad!$B$5:$B$75,MIN(71,Cartera_Polizas!$B$8+19-49))*(1+(Cartera_Polizas!$P$8-1)*MAX(0,1-19/Supuestos!$C$20))*(1-Supuestos!$C$18)^19)) -> 0.019205274 | W6: =V6*(1-MIN(1,INDEX(Tabla_Mortalidad!$B$5:$B$75,MIN(71,Cartera_Polizas!$B$8+20-49))*(1+(Cartera_Polizas!$P$8-1)*MAX(0,1-20/Supuestos!$C$20))*(1-Supuestos!$C$18)^20)) -> 0.012863467 | X6: =W6*(1-MIN(1,INDEX(Tabla_Mortalidad!$B$5:$B$75,MIN(71,Cartera_Polizas!$B$8+21-49))*(1+(Cartera_Polizas!$P$8-1)*MAX(0,1-21/Supuestos!$C$20))*(1-Supuestos!$C$18)^21)) -> 0.0082588566 | Y6: =X6*(1-MIN(1,INDEX(Tabla_Mortalidad!$B$5:$B$75,MIN(71,Cartera_Polizas!$B$8+22-49))*(1+(Cartera_Polizas!$P$8-1)*MAX(0,1-22/Supuestos!$C$20))*(1-Supuestos!$C$18)^22)) -> 0.0050622562 | Z6: =Y6*(1-MIN(1,INDEX(Tabla_Mortalidad!$B$5:$B$75,MIN(71,Cartera_Polizas!$B$8+23-49))*(1+(Cartera_Polizas!$P$8-1)*MAX(0,1-23/Supuestos!$C$20))*(1-Supuestos!$C$18)^23)) -> 0.002949564 | AA6: =Z6*(1-MIN(1,INDEX(Tabla_Mortalidad!$B$5:$B$75,MIN(71,Cartera_Polizas!$B$8+24-49))*(1+(Cartera_Polizas!$P$8-1)*MAX(0,1-24/Supuestos!$C$20))*(1-Supuestos!$C$18)^24)) -> 0.001626265 | AB6: =AA6*(1-MIN(1,INDEX(Tabla_Mortalidad!$B$5:$B$75,MIN(71,Cartera_Polizas!$B$8+25-49))*(1+(Cartera_Polizas!$P$8-1)*MAX(0,1-25/Supuestos!$C$20))*(1-Supuestos!$C$18)^25)) -> 0.00084450259 | AC6: =AB6*(1-MIN(1,INDEX(Tabla_Mortalidad!$B$5:$B$75,MIN(71,Cartera_Polizas!$B$8+26-49))*(1+(Cartera_Polizas!$P$8-1)*MAX(0,1-26/Supuestos!$C$20))*(1-Supuestos!$C$18)^26)) -> 0.00041106038 | AD6: =AC6*(1-MIN(1,INDEX(Tabla_Mortalidad!$B$5:$B$75,MIN(71,Cartera_Polizas!$B$8+27-49))*(1+(Cartera_Polizas!$P$8-1)*MAX(0,1-27/Supuestos!$C$20))*(1-Supuestos!$C$18)^27)) -> 0.00018665471 | AE6: =AD6*(1-MIN(1,INDEX(Tabla_Mortalidad!$B$5:$B$75,MIN(71,Cartera_Polizas!$B$8+28-49))*(1+(Cartera_Polizas!$P$8-1)*MAX(0,1-28/Supuestos!$C$20))*(1-Supuestos!$C$18)^28)) -> 7.8709366e-05 | AF6: =AE6*(1-MIN(1,INDEX(Tabla_Mortalidad!$B$5:$B$75,MIN(71,Cartera_Polizas!$B$8+29-49))*(1+(Cartera_Polizas!$P$8-1)*MAX(0,1-29/Supuestos!$C$20))*(1-Supuestos!$C$18)^29)) -> 3.0696018e-05 | AG6: =AF6*(1-MIN(1,INDEX(Tabla_Mortalidad!$B$5:$B$75,MIN(71,Cartera_Polizas!$B$8+30-49))*(1+(Cartera_Polizas!$P$8-1)*MAX(0,1-30/Supuestos!$C$20))*(1-Supuestos!$C$18)^30)) -> 1.1034159e-05 | AH6: =AG6*(1-MIN(1,INDEX(Tabla_Mortalidad!$B$5:$B$75,MIN(71,Cartera_Polizas!$B$8+31-49))*(1+(Cartera_Polizas!$P$8-1)*MAX(0,1-31/Supuestos!$C$20))*(1-Supuestos!$C$18)^31)) -> 3.6476302e-06 | AI6: =AH6*(1-MIN(1,INDEX(Tabla_Mortalidad!$B$5:$B$75,MIN(71,Cartera_Polizas!$B$8+32-49))*(1+(Cartera_Polizas!$P$8-1)*MAX(0,1-32/Supuestos!$C$20))*(1-Supuestos!$C$18)^32)) -> 1.1080731e-06 | AJ6: =AI6*(1-MIN(1,INDEX(Tabla_Mortalidad!$B$5:$B$75,MIN(71,Cartera_Polizas!$B$8+33-49))*(1+(Cartera_Polizas!$P$8-1)*MAX(0,1-33/Supuestos!$C$20))*(1-Supuestos!$C$18)^33)) -> 3.0969658e-07 | AK6: =AJ6*(1-MIN(1,INDEX(Tabla_Mortalidad!$B$5:$B$75,MIN(71,Cartera_Polizas!$B$8+34-49))*(1+(Cartera_Polizas!$P$8-1)*MAX(0,1-34/Supuestos!$C$20))*(1-Supuestos!$C$18)^34)) -> 7.9921387e-08 | AL6: =AK6*(1-MIN(1,INDEX(Tabla_Mortalidad!$B$5:$B$75,MIN(71,Cartera_Polizas!$B$8+35-49))*(1+(Cartera_Polizas!$P$8-1)*MAX(0,1-35/Supuestos!$C$20))*(1-Supuestos!$C$18)^35)) -> 1.9161191e-08 | AM6: =AL6*(1-MIN(1,INDEX(Tabla_Mortalidad!$B$5:$B$75,MIN(71,Cartera_Polizas!$B$8+36-49))*(1+(Cartera_Polizas!$P$8-1)*MAX(0,1-36/Supuestos!$C$20))*(1-Supuestos!$C$18)^36)) -> 4.3053724e-09 | AN6: =AM6*(1-MIN(1,INDEX(Tabla_Mortalidad!$B$5:$B$75,MIN(71,Cartera_Polizas!$B$8+37-49))*(1+(Cartera_Polizas!$P$8-1)*MAX(0,1-37/Supuestos!$C$20))*(1-Supuestos!$C$18)^37)) -> 9.166024e-10 | AO6: =AN6*(1-MIN(1,INDEX(Tabla_Mortalidad!$B$5:$B$75,MIN(71,Cartera_Polizas!$B$8+38-49))*(1+(Cartera_Polizas!$P$8-1)*MAX(0,1-38/Supuestos!$C$20))*(1-Supuestos!$C$18)^38)) -> 1.5897084e-10 | AP6: =AO6*(1-MIN(1,INDEX(Tabla_Mortalidad!$B$5:$B$75,MIN(71,Cartera_Polizas!$B$8+39-49))*(1+(Cartera_Polizas!$P$8-1)*MAX(0,1-39/Supuestos!$C$20))*(1-Supuestos!$C$18)^39)) -> 2.8228089e-11 | AQ6: =AP6*(1-MIN(1,INDEX(Tabla_Mortalidad!$B$5:$B$75,MIN(71,Cartera_Polizas!$B$8+40-49))*(1+(Cartera_Polizas!$P$8-1)*MAX(0,1-40/Supuestos!$C$20))*(1-Supuestos!$C$18)^40)) -> 5.1284758e-12 | AR6: =AQ6*(1-MIN(1,INDEX(Tabla_Mortalidad!$B$5:$B$75,MIN(71,Cartera_Polizas!$B$8+41-49))*(1+(Cartera_Polizas!$P$8-1)*MAX(0,1-41/Supuestos!$C$20))*(1-Supuestos!$C$18)^41)) -> 9.5272453e-13 | AS6: =AR6*(1-MIN(1,INDEX(Tabla_Mortalidad!$B$5:$B$75,MIN(71,Cartera_Polizas!$B$8+42-49))*(1+(Cartera_Polizas!$P$8-1)*MAX(0,1-42/Supuestos!$C$20))*(1-Supuestos!$C$18)^42)) -> 1.8086772e-13 | AT6: =AS6*(1-MIN(1,INDEX(Tabla_Mortalidad!$B$5:$B$75,MIN(71,Cartera_Polizas!$B$8+43-49))*(1+(Cartera_Polizas!$P$8-1)*MAX(0,1-43/Supuestos!$C$20))*(1-Supuestos!$C$18)^43)) -> 3.5069059e-14 | AU6: =AT6*(1-MIN(1,INDEX(Tabla_Mortalidad!$B$5:$B$75,MIN(71,Cartera_Polizas!$B$8+44-49))*(1+(Cartera_Polizas!$P$8-1)*MAX(0,1-44/Supuestos!$C$20))*(1-Supuestos!$C$18)^44)) -> 6.9410065e-15
A7: =Cartera_Polizas!A9 -> 4 | B7: =SUM(C7:AU7)+0.5 -> 8.8634763 | C7: =1-MIN(1,INDEX(Tabla_Mortalidad!$B$5:$B$75,MIN(71,Cartera_Polizas!$B$9+0-49))*(1+(Cartera_Polizas!$P$9-1)*MAX(0,1-0/Supuestos!$C$20))*(1-Supuestos!$C$18)^0) -> 0.93316243 | D7: =C7*(1-MIN(1,INDEX(Tabla_Mortalidad!$B$5:$B$75,MIN(71,Cartera_Polizas!$B$9+1-49))*(1+(Cartera_Polizas!$P$9-1)*MAX(0,1-1/Supuestos!$C$20))*(1-Supuestos!$C$18)^1)) -> 0.86619093 | E7: =D7*(1-MIN(1,INDEX(Tabla_Mortalidad!$B$5:$B$75,MIN(71,Cartera_Polizas!$B$9+2-49))*(1+(Cartera_Polizas!$P$9-1)*MAX(0,1-2/Supuestos!$C$20))*(1-Supuestos!$C$18)^2)) -> 0.79952639 | F7: =E7*(1-MIN(1,INDEX(Tabla_Mortalidad!$B$5:$B$75,MIN(71,Cartera_Polizas!$B$9+3-49))*(1+(Cartera_Polizas!$P$9-1)*MAX(0,1-3/Supuestos!$C$20))*(1-Supuestos!$C$18)^3)) -> 0.73362855 | G7: =F7*(1-MIN(1,INDEX(Tabla_Mortalidad!$B$5:$B$75,MIN(71,Cartera_Polizas!$B$9+4-49))*(1+(Cartera_Polizas!$P$9-1)*MAX(0,1-4/Supuestos!$C$20))*(1-Supuestos!$C$18)^4)) -> 0.66896921 | H7: =G7*(1-MIN(1,INDEX(Tabla_Mortalidad!$B$5:$B$75,MIN(71,Cartera_Polizas!$B$9+5-49))*(1+(Cartera_Polizas!$P$9-1)*MAX(0,1-5/Supuestos!$C$20))*(1-Supuestos!$C$18)^5)) -> 0.60602268 | I7: =H7*(1-MIN(1,INDEX(Tabla_Mortalidad!$B$5:$B$75,MIN(71,Cartera_Polizas!$B$9+6-49))*(1+(Cartera_Polizas!$P$9-1)*MAX(0,1-6/Supuestos!$C$20))*(1-Supuestos!$C$18)^6)) -> 0.54525027 | J7: =I7*(1-MIN(1,INDEX(Tabla_Mortalidad!$B$5:$B$75,MIN(71,Cartera_Polizas!$B$9+7-49))*(1+(Cartera_Polizas!$P$9-1)*MAX(0,1-7/Supuestos!$C$20))*(1-Supuestos!$C$18)^7)) -> 0.4870867 | K7: =J7*(1-MIN(1,INDEX(Tabla_Mortalidad!$B$5:$B$75,MIN(71,Cartera_Polizas!$B$9+8-49))*(1+(Cartera_Polizas!$P$9-1)*MAX(0,1-8/Supuestos!$C$20))*(1-Supuestos!$C$18)^8)) -> 0.43193026 | L7: =K7*(1-MIN(1,INDEX(Tabla_Mortalidad!$B$5:$B$75,MIN(71,Cartera_Polizas!$B$9+9-49))*(1+(Cartera_Polizas!$P$9-1)*MAX(0,1-9/Supuestos!$C$20))*(1-Supuestos!$C$18)^9)) -> 0.38012527 | M7: =L7*(1-MIN(1,INDEX(Tabla_Mortalidad!$B$5:$B$75,MIN(71,Cartera_Polizas!$B$9+10-49))*(1+(Cartera_Polizas!$P$9-1)*MAX(0,1-10/Supuestos!$C$20))*(1-Supuestos!$C$18)^10)) -> 0.33195499 | N7: =M7*(1-MIN(1,INDEX(Tabla_Mortalidad!$B$5:$B$75,MIN(71,Cartera_Polizas!$B$9+11-49))*(1+(Cartera_Polizas!$P$9-1)*MAX(0,1-11/Supuestos!$C$20))*(1-Supuestos!$C$18)^11)) -> 0.28762929 | O7: =N7*(1-MIN(1,INDEX(Tabla_Mortalidad!$B$5:$B$75,MIN(71,Cartera_Polizas!$B$9+12-49))*(1+(Cartera_Polizas!$P$9-1)*MAX(0,1-12/Supuestos!$C$20))*(1-Supuestos!$C$18)^12)) -> 0.2472792 | P7: =O7*(1-MIN(1,INDEX(Tabla_Mortalidad!$B$5:$B$75,MIN(71,Cartera_Polizas!$B$9+13-49))*(1+(Cartera_Polizas!$P$9-1)*MAX(0,1-13/Supuestos!$C$20))*(1-Supuestos!$C$18)^13)) -> 0.21095377 | Q7: =P7*(1-MIN(1,INDEX(Tabla_Mortalidad!$B$5:$B$75,MIN(71,Cartera_Polizas!$B$9+14-49))*(1+(Cartera_Polizas!$P$9-1)*MAX(0,1-14/Supuestos!$C$20))*(1-Supuestos!$C$18)^14)) -> 0.17862097 | R7: =Q7*(1-MIN(1,INDEX(Tabla_Mortalidad!$B$5:$B$75,MIN(71,Cartera_Polizas!$B$9+15-49))*(1+(Cartera_Polizas!$P$9-1)*MAX(0,1-15/Supuestos!$C$20))*(1-Supuestos!$C$18)^15)) -> 0.15017232 | S7: =R7*(1-MIN(1,INDEX(Tabla_Mortalidad!$B$5:$B$75,MIN(71,Cartera_Polizas!$B$9+16-49))*(1+(Cartera_Polizas!$P$9-1)*MAX(0,1-16/Supuestos!$C$20))*(1-Supuestos!$C$18)^16)) -> 0.1238868 | T7: =S7*(1-MIN(1,INDEX(Tabla_Mortalidad!$B$5:$B$75,MIN(71,Cartera_Polizas!$B$9+17-49))*(1+(Cartera_Polizas!$P$9-1)*MAX(0,1-17/Supuestos!$C$20))*(1-Supuestos!$C$18)^17)) -> 0.10008361 | U7: =T7*(1-MIN(1,INDEX(Tabla_Mortalidad!$B$5:$B$75,MIN(71,Cartera_Polizas!$B$9+18-49))*(1+(Cartera_Polizas!$P$9-1)*MAX(0,1-18/Supuestos!$C$20))*(1-Supuestos!$C$18)^18)) -> 0.079002906 | V7: =U7*(1-MIN(1,INDEX(Tabla_Mortalidad!$B$5:$B$75,MIN(71,Cartera_Polizas!$B$9+19-49))*(1+(Cartera_Polizas!$P$9-1)*MAX(0,1-19/Supuestos!$C$20))*(1-Supuestos!$C$18)^19)) -> 0.060787046 | W7: =V7*(1-MIN(1,INDEX(Tabla_Mortalidad!$B$5:$B$75,MIN(71,Cartera_Polizas!$B$9+20-49))*(1+(Cartera_Polizas!$P$9-1)*MAX(0,1-20/Supuestos!$C$20))*(1-Supuestos!$C$18)^20)) -> 0.045468817 | X7: =W7*(1-MIN(1,INDEX(Tabla_Mortalidad!$B$5:$B$75,MIN(71,Cartera_Polizas!$B$9+21-49))*(1+(Cartera_Polizas!$P$9-1)*MAX(0,1-21/Supuestos!$C$20))*(1-Supuestos!$C$18)^21)) -> 0.032968079 | Y7: =X7*(1-MIN(1,INDEX(Tabla_Mortalidad!$B$5:$B$75,MIN(71,Cartera_Polizas!$B$9+22-49))*(1+(Cartera_Polizas!$P$9-1)*MAX(0,1-22/Supuestos!$C$20))*(1-Supuestos!$C$18)^22)) -> 0.023098496 | Z7: =Y7*(1-MIN(1,INDEX(Tabla_Mortalidad!$B$5:$B$75,MIN(71,Cartera_Polizas!$B$9+23-49))*(1+(Cartera_Polizas!$P$9-1)*MAX(0,1-23/Supuestos!$C$20))*(1-Supuestos!$C$18)^23)) -> 0.01558494 | AA7: =Z7*(1-MIN(1,INDEX(Tabla_Mortalidad!$B$5:$B$75,MIN(71,Cartera_Polizas!$B$9+24-49))*(1+(Cartera_Polizas!$P$9-1)*MAX(0,1-24/Supuestos!$C$20))*(1-Supuestos!$C$18)^24)) -> 0.010089415 | AB7: =AA7*(1-MIN(1,INDEX(Tabla_Mortalidad!$B$5:$B$75,MIN(71,Cartera_Polizas!$B$9+25-49))*(1+(Cartera_Polizas!$P$9-1)*MAX(0,1-25/Supuestos!$C$20))*(1-Supuestos!$C$18)^25)) -> 0.0062425792 | AC7: =AB7*(1-MIN(1,INDEX(Tabla_Mortalidad!$B$5:$B$75,MIN(71,Cartera_Polizas!$B$9+26-49))*(1+(Cartera_Polizas!$P$9-1)*MAX(0,1-26/Supuestos!$C$20))*(1-Supuestos!$C$18)^26)) -> 0.0036761729 | AD7: =AC7*(1-MIN(1,INDEX(Tabla_Mortalidad!$B$5:$B$75,MIN(71,Cartera_Polizas!$B$9+27-49))*(1+(Cartera_Polizas!$P$9-1)*MAX(0,1-27/Supuestos!$C$20))*(1-Supuestos!$C$18)^27)) -> 0.0020515023 | AE7: =AD7*(1-MIN(1,INDEX(Tabla_Mortalidad!$B$5:$B$75,MIN(71,Cartera_Polizas!$B$9+28-49))*(1+(Cartera_Polizas!$P$9-1)*MAX(0,1-28/Supuestos!$C$20))*(1-Supuestos!$C$18)^28)) -> 0.0010800427 | AF7: =AE7*(1-MIN(1,INDEX(Tabla_Mortalidad!$B$5:$B$75,MIN(71,Cartera_Polizas!$B$9+29-49))*(1+(Cartera_Polizas!$P$9-1)*MAX(0,1-29/Supuestos!$C$20))*(1-Supuestos!$C$18)^29)) -> 0.00053398269 | AG7: =AF7*(1-MIN(1,INDEX(Tabla_Mortalidad!$B$5:$B$75,MIN(71,Cartera_Polizas!$B$9+30-49))*(1+(Cartera_Polizas!$P$9-1)*MAX(0,1-30/Supuestos!$C$20))*(1-Supuestos!$C$18)^30)) -> 0.00024682223 | AH7: =AG7*(1-MIN(1,INDEX(Tabla_Mortalidad!$B$5:$B$75,MIN(71,Cartera_Polizas!$B$9+31-49))*(1+(Cartera_Polizas!$P$9-1)*MAX(0,1-31/Supuestos!$C$20))*(1-Supuestos!$C$18)^31)) -> 0.0001062115 | AI7: =AH7*(1-MIN(1,INDEX(Tabla_Mortalidad!$B$5:$B$75,MIN(71,Cartera_Polizas!$B$9+32-49))*(1+(Cartera_Polizas!$P$9-1)*MAX(0,1-32/Supuestos!$C$20))*(1-Supuestos!$C$18)^32)) -> 4.2388625e-05 | AJ7: =AI7*(1-MIN(1,INDEX(Tabla_Mortalidad!$B$5:$B$75,MIN(71,Cartera_Polizas!$B$9+33-49))*(1+(Cartera_Polizas!$P$9-1)*MAX(0,1-33/Supuestos!$C$20))*(1-Supuestos!$C$18)^33)) -> 1.5642485e-05 | AK7: =AJ7*(1-MIN(1,INDEX(Tabla_Mortalidad!$B$5:$B$75,MIN(71,Cartera_Polizas!$B$9+34-49))*(1+(Cartera_Polizas!$P$9-1)*MAX(0,1-34/Supuestos!$C$20))*(1-Supuestos!$C$18)^34)) -> 5.3273209e-06 | AL7: =AK7*(1-MIN(1,INDEX(Tabla_Mortalidad!$B$5:$B$75,MIN(71,Cartera_Polizas!$B$9+35-49))*(1+(Cartera_Polizas!$P$9-1)*MAX(0,1-35/Supuestos!$C$20))*(1-Supuestos!$C$18)^35)) -> 1.6736849e-06 | AM7: =AL7*(1-MIN(1,INDEX(Tabla_Mortalidad!$B$5:$B$75,MIN(71,Cartera_Polizas!$B$9+36-49))*(1+(Cartera_Polizas!$P$9-1)*MAX(0,1-36/Supuestos!$C$20))*(1-Supuestos!$C$18)^36)) -> 4.8577832e-07 | AN7: =AM7*(1-MIN(1,INDEX(Tabla_Mortalidad!$B$5:$B$75,MIN(71,Cartera_Polizas!$B$9+37-49))*(1+(Cartera_Polizas!$P$9-1)*MAX(0,1-37/Supuestos!$C$20))*(1-Supuestos!$C$18)^37)) -> 1.3074093e-07 | AO7: =AN7*(1-MIN(1,INDEX(Tabla_Mortalidad!$B$5:$B$75,MIN(71,Cartera_Polizas!$B$9+38-49))*(1+(Cartera_Polizas!$P$9-1)*MAX(0,1-38/Supuestos!$C$20))*(1-Supuestos!$C$18)^38)) -> 3.2828693e-08 | AP7: =AO7*(1-MIN(1,INDEX(Tabla_Mortalidad!$B$5:$B$75,MIN(71,Cartera_Polizas!$B$9+39-49))*(1+(Cartera_Polizas!$P$9-1)*MAX(0,1-39/Supuestos!$C$20))*(1-Supuestos!$C$18)^39)) -> 7.7562346e-09 | AQ7: =AP7*(1-MIN(1,INDEX(Tabla_Mortalidad!$B$5:$B$75,MIN(71,Cartera_Polizas!$B$9+40-49))*(1+(Cartera_Polizas!$P$9-1)*MAX(0,1-40/Supuestos!$C$20))*(1-Supuestos!$C$18)^40)) -> 1.742399e-09 | AR7: =AQ7*(1-MIN(1,INDEX(Tabla_Mortalidad!$B$5:$B$75,MIN(71,Cartera_Polizas!$B$9+41-49))*(1+(Cartera_Polizas!$P$9-1)*MAX(0,1-41/Supuestos!$C$20))*(1-Supuestos!$C$18)^41)) -> 3.2368804e-10 | AS7: =AR7*(1-MIN(1,INDEX(Tabla_Mortalidad!$B$5:$B$75,MIN(71,Cartera_Polizas!$B$9+42-49))*(1+(Cartera_Polizas!$P$9-1)*MAX(0,1-42/Supuestos!$C$20))*(1-Supuestos!$C$18)^42)) -> 6.1449786e-11 | AT7: =AS7*(1-MIN(1,INDEX(Tabla_Mortalidad!$B$5:$B$75,MIN(71,Cartera_Polizas!$B$9+43-49))*(1+(Cartera_Polizas!$P$9-1)*MAX(0,1-43/Supuestos!$C$20))*(1-Supuestos!$C$18)^43)) -> 1.1914709e-11 | AU7: =AT7*(1-MIN(1,INDEX(Tabla_Mortalidad!$B$5:$B$75,MIN(71,Cartera_Polizas!$B$9+44-49))*(1+(Cartera_Polizas!$P$9-1)*MAX(0,1-44/Supuestos!$C$20))*(1-Supuestos!$C$18)^44)) -> 2.3582061e-12
