Workbook

Sheet LEAME
A1: Modelo ilustrativo de calificación – Titulización de Life Settlements (SPV USD 100 mm)
A2: Reconstrucción del enfoque de AM Best ('Life Settlement Securitization' + BILSM). NO es el modelo propietario de AM Best.
A4: Qué hace el modelo
A5: 1. Proyecta 25 años de flujos de una cartera de 300 vidas por cohortes (beneficios por muerte, primas, gastos, venta de remanente).
A6: 2. Aplica estrés determinístico por nivel de calificación (aaa, aa, a, bbb, bb, base): multiplicador de mortalidad (extensión de LE),
A7: penalidad por pool < 300 vidas, pérdida por default de aseguradoras, aumentos de primas (COI) y haircut del valor remanente.
A8: 3. Corre una cascada (waterfall) secuencial: interés Senior → interés Mezz → reserva de liquidez objetivo → principal Senior → principal Mezz → equity.
A9: 4. Calificación indicada: nivel de estrés más alto en el que el tramo se repaga completo al vencimiento legal (Senior además sin interés impago: pago oportuno).
A10: 5. La hoja 'Ponderacion' ajusta por factores cualitativos (notches) y aplica los chequeos de elegibilidad publicados por AM Best.
A12: Leyenda de colores
A13: Texto azul = input editable · Texto negro = fórmula · Texto verde = vínculo a otra hoja · Relleno amarillo = supuesto clave a validar.
A15: Qué está confirmado por fuentes vs. qué es supuesto
... A23: d) Lea el resultado en 'Resumen'. Detalle de flujos en las hojas CF_aaa … CF_base.

Sheet Resumen
A1: Resumen de calificación indicada
A2: Resultado del modelo ilustrativo. No es una calificación de AM Best ni una opinión de crédito.
A4: Escenario | B4: Mult. efectivo | C4: LE estresada (años) | D4: Pérdida Senior | E4: Pérdida Mezz | F4: Caja mínima c/ notas (USD mm) | G4: Años déficit | H4: WAL Senior | I4: WAL Mezz | J4: Senior pasa | K4: Mezz pasa
A5: aaa | B5: =CF_aaa!C10 -> 0.7 | C5: =CF_aaa!C93 -> 9.3305259 | D5: =CF_aaa!C86 -> 0.85693542 | E5: =CF_aaa!C87 -> 1 | F5: =CF_aaa!C89 -> 0.94001214 | G5: =CF_aaa!C90 -> 0 | H5: =CF_aaa!C91 -> 15.348002 | I5: =CF_aaa!C92 -> 0 | J5: =CF_aaa!C94 -> 0 | K5: =CF_aaa!C95 -> 0
A6: aa | B6: =CF_aa!C10 -> 0.76 | C6: =CF_aa!C93 -> 8.8779547 | D6: =CF_aa!C86 -> 0 | E6: =CF_aa!C87 -> 0.57813148 | F6: =CF_aa!C89 -> 0.64385162 | G6: =CF_aa!C90 -> 0 | H6: =CF_aa!C91 -> 13.243274 | I6: =CF_aa!C92 -> 20.359354 | J6: =CF_aa!C94 -> 1 | K6: =CF_aa!C95 -> 0
A7: a | B7: =CF_a!C10 -> 0.82 | C7: =CF_a!C93 -> 8.4709425 | D7: =CF_a!C86 -> 0 | E7: =CF_a!C87 -> 0 | F7: =CF_a!C89 -> 16.255565 | G7: =CF_a!C90 -> 0 | H7: =CF_a!C91 -> 9.270188 | I7: =CF_a!C92 -> 14.000211 | J7: =CF_a!C94 -> 1 | K7: =CF_a!C95 -> 1
A8: bbb | B8: =CF_bbb!C10 -> 0.88 | C8: =CF_bbb!C93 -> 8.1025877 | D8: =CF_bbb!C86 -> 0 | E8: =CF_bbb!C87 -> 0 | F8: =CF_bbb!C89 -> 21.926041 | G8: =CF_bbb!C90 -> 0 | H8: =CF_bbb!C91 -> 7.0561142 | I8: =CF_bbb!C92 -> 11.15277 | J8: =CF_bbb!C94 -> 1 | K8: =CF_bbb!C95 -> 1
A9: bb | B9: =CF_bb!C10 -> 0.94 | C9: =CF_bb!C93 -> 7.7673238 | D9: =CF_bb!C86 -> 0 | E9: =CF_bb!C87 -> 0 | F9: =CF_bb!C89 -> 25.809697 | G9: =CF_bb!C90 -> 0 | H9: =CF_bb!C91 -> 5.6497336 | I9: =CF_bb!C92 -> 9.407068 | J9: =CF_bb!C94 -> 1 | K9: =CF_bb!C95 -> 1
A10: base | B10: =CF_base!C10 -> 1 | C10: =CF_base!C93 -> 7.4606184 | D10: =CF_base!C86 -> 0 | E10: =CF_base!C87 -> 0 | F10: =CF_base!C89 -> 27.855196 | G10: =CF_base!C90 -> 0 | H10: =CF_base!C91 -> 4.7440768 | I10: =CF_base!C92 -> 8.1423083 | J10: =CF_base!C94 -> 1 | K10: =CF_base!C95 -> 1
A12: Escala | D12: Resultado
A13: 1 | B13: aaa | D13: Senior – índice cuantitativo | F13: =IF(J5=1,1,IF(J6=1,3,IF(J7=1,6,IF(J8=1,9,IF(J9=1,12,14))))) -> 3
A14: 2 | B14: aa+ | D14: Senior – calificación cuantitativa | F14: =INDEX($B$13:$B$26,F13) -> aa
A15: 3 | B15: aa | D15: Mezz – índice cuantitativo | F15: =IF(K5=1,1,IF(K6=1,3,IF(K7=1,6,IF(K8=1,9,IF(K9=1,12,14))))) -> 6
A16: 4 | B16: aa- | D16: Mezz – calificación cuantitativa | F16: =INDEX($B$13:$B$26,F15) -> a
A17: 5 | B17: a+ | D17: Ajuste cualitativo (notches) | F17: =Ponderacion!C31 -> -1
A18: 6 | B18: a
A19: 7 | B19: a- | D19: Senior – calificación indicada final | F19: =INDEX($B$13:$B$26,MIN(14,F13-F17)) -> aa-
A20: 8 | B20: bbb+ | D20: Mezz – calificación indicada final | F20: =INDEX($B$13:$B$26,MIN(14,F15-F17)) -> a-
A21: 9 | B21: bbb
A22: 10 | B22: bbb- | D22: Precio de compra como % del face | F22: =Cartera!C17 -> 0.22222222
A23: 11 | B23: bb+ | D23: Distribuciones a equity – caso base (USD mm) | F23: =CF_base!C96 -> 134.01544
A24: 12 | B24: bb | D24: Equity aportado (reserva inicial, USD mm) | F24: =Supuestos!C9 -> 20
A25: 13 | B25: bb- | D25: Múltiplo de equity – caso base | F25: =IFERROR(F23/F24,0) -> 6.7007721
A26: 14 | B26: b o menor

Sheet Supuestos
A1: Supuestos de estructura y estrés
B3: Parámetro | C3: Valor | D3: Unidad | E3: Fuente / nota
B5: Notas Senior | C5: 75 | D5: USD mm | E5: Supuesto (estructura ilustrativa)
B6: Cupón Senior | C6: 0.065 | D6: % anual | E6: Supuesto
B7: Notas Mezzanine | C7: 25 | D7: USD mm | E7: Supuesto
B8: Cupón Mezzanine | C8: 0.095 | D8: % anual | E8: Supuesto
B9: Reserva de liquidez inicial (fondeada por equity) | C9: 20 | D9: USD mm | E9: Supuesto
B10: Reserva objetivo (meses de primas) | C10: 12 | D10: meses | E10: Supuesto; práctica común de mercado 12–24 meses
B11: Tasa de reinversión de caja | C11: 0.03 | D11: % anual | E11: Supuesto
B12: Gastos fijos (servicer, trustee, tracking) | C12: 0.75 | D12: USD mm/año | E12: Supuesto
B13: Gasto variable sobre face en vigor | C13: 0.0005 | D13: % anual | E13: Supuesto
B14: Valor de venta de cartera remanente al vencimiento legal | C14: 0.2 | D14: % del face | E14: Supuesto
B15: Vencimiento legal (años) – fijo en 25 columnas | C15: 25 | D15: años | E15: Estructura del modelo (no editar)
B16: Umbral de vidas sin estrés adicional | C16: 300 | D16: vidas | E16: AM Best, Life Settlement Securitization (~300 vidas)
... B20: Pérdida tolerada en notas para 'pasar' el escenario | C20: 0 | D20: % del saldo | E20: Supuesto (equivale a pago completo y oportuno)
B22: Matriz de estrés por nivel de calificación (determinística)
B23: Escenario | C23: Multiplicador de mortalidad (q) | D23: Penalidad pool < umbral (resta al mult.) | E23: Pérdida por default de aseguradoras (% beneficio) | F23: Aumento anual de primas (COI) | G23: Haircut valor remanente | H23: Fuente / nota
B24: aaa | C24: 0.7 | D24: 0.05 | E24: 0.06 | F24: 0.02 | G24: 0.5 | H24: Estimación de Claude – calibrar con criterio vigente de AM Best
B25: aa | C25: 0.76 | D25: 0.04 | E25: 0.045 | F25: 0.015 | G25: 0.4 | H25: Estimación de Claude – calibrar con criterio vigente de AM Best
B26: a | C26: 0.82 | D26: 0.03 | E26: 0.03 | F26: 0.01 | G26: 0.3 | H26: Estimación de Claude – calibrar con criterio vigente de AM Best
B27: bbb | C27: 0.88 | D27: 0.02 | E27: 0.02 | F27: 0.005 | G27: 0.2 | H27: Estimación de Claude – calibrar con criterio vigente de AM Best
B28: bb | C28: 0.94 | D28: 0.01 | E28: 0.01 | F28: 0.0025 | G28: 0.1 | H28: Estimación de Claude – calibrar con criterio vigente de AM Best
B29: base | C29: 1 | D29: 0 | E29: 0.005 | F29: 0 | G29: 0 | H29: Caso esperado (LE de los proveedores sin ajuste)
B31: Nota: multiplicador < 1 reduce la probabilidad anual de muerte = extiende la LE (el riesgo central del inversionista). AM Best publica que usa la tabla 2015 VBT (revisión 2026) como base de mortalidad; aquí se aproxima con una curva por cohorte.

Sheet Cartera
A1: Cinta de datos agregada por cohortes (input)
A4: Cohorte | B4: Descripción | C4: Vidas | D4: Face (USD mm) | E4: Edad prom. | F4: q0 (prob. muerte año 1) | G4: Crec. anual de mortalidad | H4: Prima anual (% face) | I4: FSR prom. aseguradoras | J4: Mayor póliza individual (USD mm) | K4: LE implícita base (años) | L4: % del face
A5: C1 | B5: Edad 75–79, salud estándar | C5: 70 | D5: 90 | E5: 77 | F5: 0.045 | G5: 0.11 | H5: 0.04 | I5: A+ | J5: 2.5 | K5: =LE!C4 -> 9.6046412 | L5: =D5/$D$10 -> 0.2
A6: C2 | B6: Edad 80–84, deterioro moderado | C6: 80 | D6: 120 | E6: 82 | F6: 0.065 | G6: 0.1 | H6: 0.05 | I6: A | J6: 3 | K6: =LE!C5 -> 7.9397814 | L6: =D6/$D$10 -> 0.26666667
A7: C3 | B7: Edad 85–89, deterioro significativo | C7: 60 | D7: 100 | E7: 86 | F7: 0.095 | G7: 0.09 | H7: 0.06 | I7: A | J7: 3 | K7: =LE!C6 -> 6.3151825 | L7: =D7/$D$10 -> 0.22222222
A8: C4 | B8: Edad 90+, deterioro severo | C8: 50 | D8: 80 | E8: 91 | F8: 0.14 | G8: 0.08 | H8: 0.07 | I8: A- | J8: 2.5 | K8: =LE!C7 -> 4.814024 | L8: =D8/$D$10 -> 0.17777778
A9: C5 | B9: Edad 70–74, enfermedad crónica | C9: 40 | D9: 60 | E9: 72 | F9: 0.05 | G9: 0.12 | H9: 0.035 | I9: A+ | J9: 2 | K9: =LE!C8 -> 8.725913 | L9: =D9/$D$10 -> 0.13333333
A10: Total / Prom. | C10: =SUM(C5:C9) -> 300 | D10: =SUM(D5:D9) -> 450 | E10: =SUMPRODUCT(E5:E9,D5:D9)/D10 -> 82.155556 | J10: =MAX(J5:J9) -> 3 | K10: =SUMPRODUCT(K5:K9,D5:D9)/D10 -> 7.4608587 | L10: =SUM(L5:L9) -> 1
A13: Datos de underwriting
B14: Antigüedad de reportes LE (meses) | C14: 8
B15: # proveedores de LE independientes por vida | C15: 2
B16: Precio de compra de la cartera (USD mm) | C16: =Supuestos!C5+Supuestos!C7 -> 100
B17: Precio como % del face | C17: =C16/D10 -> 0.22222222
B18: Mayor póliza como % del face | C18: =J10/D10 -> 0.0066666667
A20: Nota: reemplace las cohortes con su cinta real. Para precisión de rating, AM Best trabaja póliza por póliza con las LE de ambos proveedores; las cohortes son una simplificación.

Sheet LE
A1: Supervivencia base por cohorte (sin estrés) – cálculo de LE implícita
A2: Curva: q(t) = MIN(1, q0 × (1+g)^(t−1)). LE ≈ Σ supervivencia fin de año + 0.5. Horizonte 40 años.
A3: Cohorte | C3: LE (años) | D3: 1 | E3: 2 | F3: 3 | G3: 4 | H3: 5 | I3: 6 | J3: 7 | K3: 8 | L3: 9 | M3: 10 | N3: 11 | O3: 12 | P3: 13 | Q3: 14 | R3: 15 | S3: 16 | T3: 17 | U3: 18 | V3: 19 | W3: 20 | X3: 21 | Y3: 22 | Z3: 23 | AA3: 24 | AB3: 25 | AC3: 26 | AD3: 27 | AE3: 28 | AF3: 29 | AG3: 30 | AH3: 31 | AI3: 32 | AJ3: 33 | AK3: 34 | AL3: 35 | AM3: 36 | AN3: 37 | AO3: 38 | AP3: 39 | AQ3: 40
A4: =Cartera!A5 -> C1 | C4: =SUM(D4:AQ4)+0.5 -> 9.6046412 | D4: =1-MIN(1,Cartera!$F$5*(1+Cartera!$G$5)^(1-1)) -> 0.955 | E4: =D4*(1-MIN(1,Cartera!$F$5*(1+Cartera!$G$5)^(2-1))) -> 0.90729775 | F4: =E4*(1-MIN(1,Cartera!$F$5*(1+Cartera!$G$5)^(3-1))) -> 0.85699308 | G4: =F4*(1-MIN(1,Cartera!$F$5*(1+Cartera!$G$5)^(4-1))) -> 0.80425082 | H4: =G4*(1-MIN(1,Cartera!$F$5*(1+Cartera!$G$5)^(5-1))) -> 0.74930989 | I4: =H4*(1-MIN(1,Cartera!$F$5*(1+Cartera!$G$5)^(6-1))) -> 0.69249151 | J4: =I4*(1-MIN(1,Cartera!$F$5*(1+Cartera!$G$5)^(7-1))) -> 0.63420543 | K4: =J4*(1-MIN(1,Cartera!$F$5*(1+Cartera!$G$5)^(8-1))) -> 0.57495339 | L4: =K4*(1-MIN(1,Cartera!$F$5*(1+Cartera!$G$5)^(9-1))) -> 0.51532831 | M4: =L4*(1-MIN(1,Cartera!$F$5*(1+Cartera!$G$5)^(10-1))) -> 0.45600801 | N4: =M4*(1-MIN(1,Cartera!$F$5*(1+Cartera!$G$5)^(11-1))) -> 0.39774207 | O4: =N4*(1-MIN(1,Cartera!$F$5*(1+Cartera!$G$5)^(12-1))) -> 0.34133068 | P4: =O4*(1-MIN(1,Cartera!$F$5*(1+Cartera!$G$5)^(13-1))) -> 0.28759489 | Q4: =P4*(1-MIN(1,Cartera!$F$5*(1+Cartera!$G$5)^(14-1))) -> 0.23733837 | R4: =Q4*(1-MIN(1,Cartera!$F$5*(1+Cartera!$G$5)^(15-1))) -> 0.19130189 | S4: =R4*(1-MIN(1,Cartera!$F$5*(1+Cartera!$G$5)^(16-1))) -> 0.15011334 | T4: =S4*(1-MIN(1,Cartera!$F$5*(1+Cartera!$G$5)^(17-1))) -> 0.11423772 | U4: =T4*(1-MIN(1,Cartera!$F$5*(1+Cartera!$G$5)^(18-1))) -> 0.083932831 | V4: =U4*(1-MIN(1,Cartera!$F$5*(1+Cartera!$G$5)^(19-1))) -> 0.059217979 | W4: =V4*(1-MIN(1,Cartera!$F$5*(1+Cartera!$G$5)^(20-1))) -> 0.039862555 | X4: =W4*(1-MIN(1,Cartera!$F$5*(1+Cartera!$G$5)^(21-1))) -> 0.02540026 | Y4: =X4*(1-MIN(1,Cartera!$F$5*(1+Cartera!$G$5)^(22-1))) -> 0.015171259 | Z4: =Y4*(1-MIN(1,Cartera!$F$5*(1+Cartera!$G$5)^(23-1))) -> 0.0083895417 | AA4: =Z4*(1-MIN(1,Cartera!$F$5*(1+Cartera!$G$5)^(24-1))) -> 0.0042268019 | AB4: =AA4*(1-MIN(1,Cartera!$F$5*(1+Cartera!$G$5)^(25-1))) -> 0.0018988399 | AC4: =AB4*(1-MIN(1,Cartera!$F$5*(1+Cartera!$G$5)^(26-1))) -> 0.00073799195 | AD4: =AC4*(1-MIN(1,Cartera!$F$5*(1+Cartera!$G$5)^(27-1))) -> 0.0002371951 | AE4: =AD4*(1-MIN(1,Cartera!$F$5*(1+Cartera!$G$5)^(28-1))) -> 5.8530442e-05 | AF4: =AE4*(1-MIN(1,Cartera!$F$5*(1+Cartera!$G$5)^(29-1))) -> 9.593399e-06 | AG4: =AF4*(1-MIN(1,Cartera!$F$5*(1+Cartera!$G$5)^(30-1))) -> 6.9009082e-07 | AH4: =AG4*(1-MIN(1,Cartera!$F$5*(1+Cartera!$G$5)^(31-1))) -> 0 | AI4: =AH4*(1-MIN(1,Cartera!$F$5*(1+Cartera!$G$5)^(32-1))) -> 0 | AJ4: =AI4*(1-MIN(1,Cartera!$F$5*(1+Cartera!$G$5)^(33-1))) -> 0 | AK4: =AJ4*(1-MIN(1,Cartera!$F$5*(1+Cartera!$G$5)^(34-1))) -> 0 | AL4: =AK4*(1-MIN(1,Cartera!$F$5*(1+Cartera!$G$5)^(35-1))) -> 0 | AM4: =AL4*(1-MIN(1,Cartera!$F$5*(1+Cartera!$G$5)^(36-1))) -> 0 | AN4: =AM4*(1-MIN(1,Cartera!$F$5*(1+Cartera!$G$5)^(37-1))) -> 0 | AO4: =AN4*(1-MIN(1,Cartera!$F$5*(1+Cartera!$G$5)^(38-1))) -> 0 | AP4: =AO4*(1-MIN(1,Cartera!$F$5*(1+Cartera!$G$5)^(39-1))) -> 0 | AQ4: =AP4*(1-MIN(1,Cartera!$F$5*(1+Cartera!$G$5)^(40-1))) -> 0
A5: =Cartera!A6 -> C2 | C5: =SUM(D5:AQ5)+0.5 -> 7.9397814 | D5: =1-MIN(1,Cartera!$F$6*(1+Cartera!$G$6)^(1-1)) -> 0.935 | E5: =D5*(1-MIN(1,Cartera!$F$6*(1+Cartera!$G$6)^(2-1))) -> 0.8681475 | F5: =E5*(1-MIN(1,Cartera!$F$6*(1+Cartera!$G$6)^(3-1))) -> 0.7998677 | G5: =F5*(1-MIN(1,Cartera!$F$6*(1+Cartera!$G$6)^(4-1))) -> 0.73066715 | H5: =G5*(1-MIN(1,Cartera!$F$6*(1+Cartera!$G$6)^(5-1))) -> 0.66113211 | I5: =H5*(1-MIN(1,Cartera!$F$6*(1+Cartera!$G$6)^(6-1))) -> 0.59192272 | J5: =I5*(1-MIN(1,Cartera!$F$6*(1+Cartera!$G$6)^(7-1))) -> 0.52376195 | K5: =J5*(1-MIN(1,Cartera!$F$6*(1+Cartera!$G$6)^(8-1))) -> 0.4574188 | L5: =K5*(1-MIN(1,Cartera!$F$6*(1+Cartera!$G$6)^(9-1))) -> 0.39368514 | M5: =L5*(1-MIN(1,Cartera!$F$6*(1+Cartera!$G$6)^(10-1))) -> 0.33334636 | N5: =M5*(1-MIN(1,Cartera!$F$6*(1+Cartera!$G$6)^(11-1))) -> 0.27714641 | O5: =N5*(1-MIN(1,Cartera!$F$6*(1+Cartera!$G$6)^(12-1))) -> 0.22574889 | P5: =O5*(1-MIN(1,Cartera!$F$6*(1+Cartera!$G$6)^(13-1))) -> 0.1796966 | Q5: =P5*(1-MIN(1,Cartera!$F$6*(1+Cartera!$G$6)^(14-1))) -> 0.13937311 | R5: =Q5*(1-MIN(1,Cartera!$F$6*(1+Cartera!$G$6)^(15-1))) -> 0.10497062 | S5: =R5*(1-MIN(1,Cartera!$F$6*(1+Cartera!$G$6)^(16-1))) -> 0.076468876 | T5: =S5*(1-MIN(1,Cartera!$F$6*(1+Cartera!$G$6)^(17-1))) -> 0.053629669 | U5: =T5*(1-MIN(1,Cartera!$F$6*(1+Cartera!$G$6)^(18-1))) -> 0.036010147 | V5: =U5*(1-MIN(1,Cartera!$F$6*(1+Cartera!$G$6)^(19-1))) -> 0.022996273 | W5: =V5*(1-MIN(1,Cartera!$F$6*(1+Cartera!$G$6)^(20-1))) -> 0.013854471 | X5: =W5*(1-MIN(1,Cartera!$F$6*(1+Cartera!$G$6)^(21-1))) -> 0.0077960839 | Y5: =X5*(1-MIN(1,Cartera!$F$6*(1+Cartera!$G$6)^(22-1))) -> 0.0040460409 | Z5: =Y5*(1-MIN(1,Cartera!$F$6*(1+Cartera!$G$6)^(23-1))) -> 0.0019052084 | AA5: =Z5*(1-MIN(1,Cartera!$F$6*(1+Cartera!$G$6)^(24-1))) -> 0.00079632059 | AB5: =AA5*(1-MIN(1,Cartera!$F$6*(1+Cartera!$G$6)^(25-1))) -> 0.00028649017 | AC5: =AB5*(1-MIN(1,Cartera!$F$6*(1+Cartera!$G$6)^(26-1))) -> 8.4727781e-05 | AD5: =AC5*(1-MIN(1,Cartera!$F$6*(1+Cartera!$G$6)^(27-1))) -> 1.9090739e-05 | AE5: =AD5*(1-MIN(1,Cartera!$F$6*(1+Cartera!$G$6)^(28-1))) -> 2.8225729e-06 | AF5: =AE5*(1-MIN(1,Cartera!$F$6*(1+Cartera!$G$6)^(29-1))) -> 1.7679303e-07 | AG5: =AF5*(1-MIN(1,Cartera!$F$6*(1+Cartera!$G$6)^(30-1))) -> 0 | AH5: =AG5*(1-MIN(1,Cartera!$F$6*(1+Cartera!$G$6)^(31-1))) -> 0 | AI5: =AH5*(1-MIN(1,Cartera!$F$6*(1+Cartera!$G$6)^(32-1))) -> 0 | AJ5: =AI5*(1-MIN(1,Cartera!$F$6*(1+Cartera!$G$6)^(33-1))) -> 0 | AK5: =AJ5*(1-MIN(1,Cartera!$F$6*(1+Cartera!$G$6)^(34-1))) -> 0 | AL5: =AK5*(1-MIN(1,Cartera!$F$6*(1+Cartera!$G$6)^(35-1))) -> 0 | AM5: =AL5*(1-MIN(1,Cartera!$F$6*(1+Cartera!$G$6)^(36-1))) -> 0 | AN5: =AM5*(1-MIN(1,Cartera!$F$6*(1+Cartera!$G$6)^(37-1))) -> 0 | AO5: =AN5*(1-MIN(1,Cartera!$F$6*(1+Cartera!$G$6)^(38-1))) -> 0 | AP5: =AO5*(1-MIN(1,Cartera!$F$6*(1+Cartera!$G$6)^(39-1))) -> 0 | AQ5: =AP5*(1-MIN(1,Cartera!$F$6*(1+Cartera!$G$6)^(40-1))) -> 0
A6: =Cartera!A7 -> C3 | C6: =SUM(D6:AQ6)+0.5 -> 6.3151825 | D6: =1-MIN(1,Cartera!$F$7*(1+Cartera!$G$7)^(1-1)) -> 0.905 | E6: =D6*(1-MIN(1,Cartera!$F$7*(1+Cartera!$G$7)^(2-1))) -> 0.81128725 | F6: =E6*(1-MIN(1,Cartera!$F$7*(1+Cartera!$G$7)^(3-1))) -> 0.71971766 | G6: =F6*(1-MIN(1,Cartera!$F$7*(1+Cartera!$G$7)^(4-1))) -> 0.63117242 | H6: =G6*(1-MIN(1,Cartera!$F$7*(1+Cartera!$G$7)^(5-1))) -> 0.54653203 | I6: =H6*(1-MIN(1,Cartera!$F$7*(1+Cartera!$G$7)^(6-1))) -> 0.46664584 | J6: =I6*(1-MIN(1,Cartera!$F$7*(1+Cartera!$G$7)^(7-1))) -> 0.39229772 | K6: =J6*(1-MIN(1,Cartera!$F$7*(1+Cartera!$G$7)^(8-1))) -> 0.32416984 | L6: =K6*(1-MIN(1,Cartera!$F$7*(1+Cartera!$G$7)^(9-1))) -> 0.26280661 | M6: =L6*(1-MIN(1,Cartera!$F$7*(1+Cartera!$G$7)^(10-1))) -> 0.20858176 | N6: =M6*(1-MIN(1,Cartera!$F$7*(1+Cartera!$G$7)^(11-1))) -> 0.16167182 | O6: =N6*(1-MIN(1,Cartera!$F$7*(1+Cartera!$G$7)^(12-1))) -> 0.12203951 | P6: =O6*(1-MIN(1,Cartera!$F$7*(1+Cartera!$G$7)^(13-1))) -> 0.089430165 | Q6: =P6*(1-MIN(1,Cartera!$F$7*(1+Cartera!$G$7)^(14-1))) -> 0.063383501 | R6: =Q6*(1-MIN(1,Cartera!$F$7*(1+Cartera!$G$7)^(15-1))) -> 0.043261517 | S6: =R6*(1-MIN(1,Cartera!$F$7*(1+Cartera!$G$7)^(16-1))) -> 0.028291482 | T6: =S6*(1-MIN(1,Cartera!$F$7*(1+Cartera!$G$7)^(17-1))) -> 0.017620527 | U6: =T6*(1-MIN(1,Cartera!$F$7*(1+Cartera!$G$7)^(18-1))) -> 0.010376285 | V6: =U6*(1-MIN(1,Cartera!$F$7*(1+Cartera!$G$7)^(19-1))) -> 0.0057263973 | W6: =V6*(1-MIN(1,Cartera!$F$7*(1+Cartera!$G$7)^(20-1))) -> 0.0029292938 | X6: =W6*(1-MIN(1,Cartera!$F$7*(1+Cartera!$G$7)^(21-1))) -> 0.001369682 | Y6: =X6*(1-MIN(1,Cartera!$F$7*(1+Cartera!$G$7)^(22-1))) -> 0.00057480524 | Z6: =Y6*(1-MIN(1,Cartera!$F$7*(1+Cartera!$G$7)^(23-1))) -> 0.00021120239 | AA6: =Z6*(1-MIN(1,Cartera!$F$7*(1+Cartera!$G$7)^(24-1))) -> 6.5578749e-05 | AB6: =AA6*(1-MIN(1,Cartera!$F$7*(1+Cartera!$G$7)^(25-1))) -> 1.629285e-05 | AC6: =AB6*(1-MIN(1,Cartera!$F$7*(1+Cartera!$G$7)^(26-1))) -> 2.9458668e-06 | AD6: =AC6*(1-MIN(1,Cartera!$F$7*(1+Cartera!$G$7)^(27-1))) -> 3.1544341e-07 | AE6: =AD6*(1-MIN(1,Cartera!$F$7*(1+Cartera!$G$7)^(28-1))) -> 8.4277638e-09 | AF6: =AE6*(1-MIN(1,Cartera!$F$7*(1+Cartera!$G$7)^(29-1))) -> 0 | AG6: =AF6*(1-MIN(1,Cartera!$F$7*(1+Cartera!$G$7)^(30-1))) -> 0 | AH6: =AG6*(1-MIN(1,Cartera!$F$7*(1+Cartera!$G$7)^(31-1))) -> 0 | AI6: =AH6*(1-MIN(1,Cartera!$F$7*(1+Cartera!$G$7)^(32-1))) -> 0 | AJ6: =AI6*(1-MIN(1,Cartera!$F$7*(1+Cartera!$G$7)^(33-1))) -> 0 | AK6: =AJ6*(1-MIN(1,Cartera!$F$7*(1+Cartera!$G$7)^(34-1))) -> 0 | AL6: =AK6*(1-MIN(1,Cartera!$F$7*(1+Cartera!$G$7)^(35-1))) -> 0 | AM6: =AL6*(1-MIN(1,Cartera!$F$7*(1+Cartera!$G$7)^(36-1))) -> 0 | AN6: =AM6*(1-MIN(1,Cartera!$F$7*(1+Cartera!$G$7)^(37-1))) -> 0 | AO6: =AN6*(1-MIN(1,Cartera!$F$7*(1+Cartera!$G$7)^(38-1))) -> 0 | AP6: =AO6*(1-MIN(1,Cartera!$F$7*(1+Cartera!$G$7)^(39-1))) -> 0 | AQ6: =AP6*(1-MIN(1,Cartera!$F$7*(1+Cartera!$G$7)^(40-1))) -> 0
A7: =Cartera!A8 -> C4 | C7: =SUM(D7:AQ7)+0.5 -> 4.814024 | D7: =1-MIN(1,Cartera!$F$8*(1+Cartera!$G$8)^(1-1)) -> 0.86 | E7: =D7*(1-MIN(1,Cartera!$F$8*(1+Cartera!$G$8)^(2-1))) -> 0.729968 | F7: =E7*(1-MIN(1,Cartera!$F$8*(1+Cartera!$G$8)^(3-1))) -> 0.61076715 | G7: =F7*(1-MIN(1,Cartera!$F$8*(1+Cartera!$G$8)^(4-1))) -> 0.50305245 | H7: =G7*(1-MIN(1,Cartera!$F$8*(1+Cartera!$G$8)^(5-1))) -> 0.40723683 | I7: =H7*(1-MIN(1,Cartera!$F$8*(1+Cartera!$G$8)^(6-1))) -> 0.32346579 | J7: =I7*(1-MIN(1,Cartera!$F$8*(1+Cartera!$G$8)^(7-1))) -> 0.25160386 | K7: =J7*(1-MIN(1,Cartera!$F$8*(1+Cartera!$G$8)^(8-1))) -> 0.19123518 | L7: =K7*(1-MIN(1,Cartera!$F$8*(1+Cartera!$G$8)^(9-1))) -> 0.14168037 | M7: =L7*(1-MIN(1,Cartera!$F$8*(1+Cartera!$G$8)^(10-1))) -> 0.10202961 | N7: =M7*(1-MIN(1,Cartera!$F$8*(1+Cartera!$G$8)^(11-1))) -> 0.07119121 | O7: =N7*(1-MIN(1,Cartera!$F$8*(1+Cartera!$G$8)^(12-1))) -> 0.047952302 | P7: =O7*(1-MIN(1,Cartera!$F$8*(1+Cartera!$G$8)^(13-1))) -> 0.031047014 | Q7: =P7*(1-MIN(1,Cartera!$F$8*(1+Cartera!$G$8)^(14-1))) -> 0.019225947 | R7: =Q7*(1-MIN(1,Cartera!$F$8*(1+Cartera!$G$8)^(15-1))) -> 0.011320101 | S7: =R7*(1-MIN(1,Cartera!$F$8*(1+Cartera!$G$8)^(16-1))) -> 0.0062928024 | T7: =S7*(1-MIN(1,Cartera!$F$8*(1+Cartera!$G$8)^(17-1))) -> 0.0032745732 | U7: =T7*(1-MIN(1,Cartera!$F$8*(1+Cartera!$G$8)^(18-1))) -> 0.001578336 | V7: =U7*(1-MIN(1,Cartera!$F$8*(1+Cartera!$G$8)^(19-1))) -> 0.0006953474 | W7: =V7*(1-MIN(1,Cartera!$F$8*(1+Cartera!$G$8)^(20-1))) -> 0.00027521979 | X7: =W7*(1-MIN(1,Cartera!$F$8*(1+Cartera!$G$8)^(21-1))) -> 9.5629519e-05 | Y7: =X7*(1-MIN(1,Cartera!$F$8*(1+Cartera!$G$8)^(22-1))) -> 2.8235886e-05 | Z7: =Y7*(1-MIN(1,Cartera!$F$8*(1+Cartera!$G$8)^(23-1))) -> 6.7451109e-06 | AA7: =Z7*(1-MIN(1,Cartera!$F$8*(1+Cartera!$G$8)^(24-1))) -> 1.2005966e-06 | AB7: =AA7*(1-MIN(1,Cartera!$F$8*(1+Cartera!$G$8)^(25-1))) -> 1.347486e-07 | AC7: =AB7*(1-MIN(1,Cartera!$F$8*(1+Cartera!$G$8)^(26-1))) -> 5.5534577e-09 | AD7: =AC7*(1-MIN(1,Cartera!$F$8*(1+Cartera!$G$8)^(27-1))) -> 0 | AE7: =AD7*(1-MIN(1,Cartera!$F$8*(1+Cartera!$G$8)^(28-1))) -> 0 | AF7: =AE7*(1-MIN(1,Cartera!$F$8*(1+Cartera!$G$8)^(29-1))) -> 0 | AG7: =AF7*(1-MIN(1,Cartera!$F$8*(1+Cartera!$G$8)^(30-1))) -> 0 | AH7: =AG7*(1-MIN(1,Cartera!$F$8*(1+Cartera!$G$8)^(31-1))) -> 0 | AI7: =AH7*(1-MIN(1,Cartera!$F$8*(1+Cartera!$G$8)^(32-1))) -> 0 | AJ7: =AI7*(1-MIN(1,Cartera!$F$8*(1+Cartera!$G$8)^(33-1))) -> 0 | AK7: =AJ7*(1-MIN(1,Cartera!$F$8*(1+Cartera!$G$8)^(34-1))) -> 0 | AL7: =AK7*(1-MIN(1,Cartera!$F$8*(1+Cartera!$G$8)^(35-1))) -> 0 | AM7: =AL7*(1-MIN(1,Cartera!$F$8*(1+Cartera!$G$8)^(36-1))) -> 0 | AN7: =AM7*(1-MIN(1,Cartera!$F$8*(1+Cartera!$G$8)^(37-1))) -> 0 | AO7: =AN7*(1-MIN(1,Cartera!$F$8*(1+Cartera!$G$8)^(38-1))) -> 0 | AP7: =AO7*(1-MIN(1,Cartera!$F$8*(1+Cartera!$G$8)^(39-1))) -> 0 | AQ7: =AP7*(1-MIN(1,Cartera!$F$8*(1+Cartera!$G$8)^(40-1))) -> 0
A8: =Cartera!A9 -> C5 | C8: =SUM(D8:AQ8)+0.5 -> 8.725913 | D8: =1-MIN(1,Cartera!$F$9*(1+Cartera!$G$9)^(1-1)) -> 0.95 | E8: =D8*(1-MIN(1,Cartera!$F$9*(1+Cartera!$G$9)^(2-1))) -> 0.8968 | F8: =E8*(1-MIN(1,Cartera!$F$9*(1+Cartera!$G$9)^(3-1))) -> 0.8405527 | G8: =F8*(1-MIN(1,Cartera!$F$9*(1+Cartera!$G$9)^(4-1))) -> 0.7815069 | H8: =G8*(1-MIN(1,Cartera!$F$9*(1+Cartera!$G$9)^(5-1))) -> 0.72002109 | I8: =H8*(1-MIN(1,Cartera!$F$9*(1+Cartera!$G$9)^(6-1))) -> 0.65657493 | J8: =I8*(1-MIN(1,Cartera!$F$9*(1+Cartera!$G$9)^(7-1))) -> 0.59177681 | K8: =J8*(1-MIN(1,Cartera!$F$9*(1+Cartera!$G$9)^(8-1))) -> 0.52636531 | L8: =K8*(1-MIN(1,Cartera!$F$9*(1+Cartera!$G$9)^(9-1))) -> 0.46120225 | M8: =L8*(1-MIN(1,Cartera!$F$9*(1+Cartera!$G$9)^(10-1))) -> 0.39725474 | N8: =M8*(1-MIN(1,Cartera!$F$9*(1+Cartera!$G$9)^(11-1))) -> 0.3355641 | O8: =N8*(1-MIN(1,Cartera!$F$9*(1+Cartera!$G$9)^(12-1))) -> 0.27720027 | P8: =O8*(1-MIN(1,Cartera!$F$9*(1+Cartera!$G$9)^(13-1))) -> 0.22320199 | Q8: =P8*(1-MIN(1,Cartera!$F$9*(1+Cartera!$G$9)^(14-1))) -> 0.17450497 | R8: =Q8*(1-MIN(1,Cartera!$F$9*(1+Cartera!$G$9)^(15-1))) -> 0.1318637 | S8: =R8*(1-MIN(1,Cartera!$F$9*(1+Cartera!$G$9)^(16-1))) -> 0.095775471 | T8: =S8*(1-MIN(1,Cartera!$F$9*(1+Cartera!$G$9)^(17-1))) -> 0.066418404 | U8: =T8*(1-MIN(1,Cartera!$F$9*(1+Cartera!$G$9)^(18-1))) -> 0.04361683 | V8: =U8*(1-MIN(1,Cartera!$F$9*(1+Cartera!$G$9)^(19-1))) -> 0.026846234 | W8: =V8*(1-MIN(1,Cartera!$F$9*(1+Cartera!$G$9)^(20-1))) -> 0.015285223 | X8: =W8*(1-MIN(1,Cartera!$F$9*(1+Cartera!$G$9)^(21-1))) -> 0.007912936 | Y8: =X8*(1-MIN(1,Cartera!$F$9*(1+Cartera!$G$9)^(22-1))) -> 0.003638428 | Z8: =Y8*(1-MIN(1,Cartera!$F$9*(1+Cartera!$G$9)^(23-1))) -> 0.0014371226 | AA8: =Z8*(1-MIN(1,Cartera!$F$9*(1+Cartera!$G$9)^(24-1))) -> 0.00046330339 | AB8: =AA8*(1-MIN(1,Cartera!$F$9*(1+Cartera!$G$9)^(25-1))) -> 0.00011168788 | AC8: =AB8*(1-MIN(1,Cartera!$F$9*(1+Cartera!$G$9)^(26-1))) -> 1.6752822e-05 | AD8: =AC8*(1-MIN(1,Cartera!$F$9*(1+Cartera!$G$9)^(27-1))) -> 8.0407503e-07 | AE8: =AD8*(1-MIN(1,Cartera!$F$9*(1+Cartera!$G$9)^(28-1))) -> 0 | AF8: =AE8*(1-MIN(1,Cartera!$F$9*(1+Cartera!$G$9)^(29-1))) -> 0 | AG8: =AF8*(1-MIN(1,Cartera!$F$9*(1+Cartera!$G$9)^(30-1))) -> 0 | AH8: =AG8*(1-MIN(1,Cartera!$F$9*(1+Cartera!$G$9)^(31-1))) -> 0 | AI8: =AH8*(1-MIN(1,Cartera!$F$9*(1+Cartera!$G$9)^(32-1))) -> 0 | AJ8: =AI8*(1-MIN(1,Cartera!$F$9*(1+Cartera!$G$9)^(33-1))) -> 0 | AK8: =AJ8*(1-MIN(1,Cartera!$F$9*(1+Cartera!$G$9)^(34-1))) -> 0 | AL8: =AK8*(1-MIN(1,Cartera!$F$9*(1+Cartera!$G$9)^(35-1))) -> 0 | AM8: =AL8*(1-MIN(1,Cartera!$F$9*(1+Cartera!$G$9)^(36-1))) -> 0 | AN8: =AM8*(1-MIN(1,Cartera!$F$9*(1+Cartera!$G$9)^(37-1))) -> 0 | AO8: =AN8*(1-MIN(1,Cartera!$F$9*(1+Cartera!$G$9)^(38-1))) -> 0 | AP8: =AO8*(1-MIN(1,Cartera!$F$9*(1+Cartera!$G$9)^(39-1))) -> 0 | AQ8: =AP8*(1-MIN(1,Cartera!$F$9*(1+Cartera!$G$9)^(40-1))) -> 0

Sheet CF_aaa
A1: Flujo de caja y cascada – escenario aaa
A2: Escenario | C2: aaa
A3: Año | D3: 1 | E3: 2 | F3: 3 | G3: 4 | H3: 5 | I3: 6 | J3: 7 | K3: 8 | L3: 9 | M3: 10 | N3: 11 | O3: 12 | P3: 13 | Q3: 14 | R3: 15 | S3: 16 | T3: 17 | U3: 18 | V3: 19 | W3: 20 | X3: 21 | Y3: 22 | Z3: 23 | AA3: 24 | AB3: 25
A5: Multiplicador de mortalidad | C5: =Supuestos!C24 -> 0.7
A6: Penalidad pool pequeño | C6: =Supuestos!D24 -> 0.05
A7: Pérdida default aseguradoras | C7: =Supuestos!E24 -> 0.06
A8: Aumento anual de primas | C8: =Supuestos!F24 -> 0.02
A9: Haircut valor remanente | C9: =Supuestos!G24 -> 0.5
A10: Multiplicador efectivo | C10: =MAX(0,C5-IF(Cartera!C10<Supuestos!C16,C6,0)) -> 0.7
A12: =Cartera!A5&" – "&Cartera!B5 -> C1 – Edad 75–79, salud estándar
B13: q estresada | D13: =MIN(1,Cartera!$F$5*(1+Cartera!$G$5)^(D$3-1)*$C$10) -> 0.0315 | E13: =MIN(1,Cartera!$F$5*(1+Cartera!$G$5)^(E$3-1)*$C$10) -> 0.034965 | F13: =MIN(1,Cartera!$F$5*(1+Cartera!$G$5)^(F$3-1)*$C$10) -> 0.03881115 | G13: =MIN(1,Cartera!$F$5*(1+Cartera!$G$5)^(G$3-1)*$C$10) -> 0.043080377 | H13: =MIN(1,Cartera!$F$5*(1+Cartera!$G$5)^(H$3-1)*$C$10) -> 0.047819218 | I13: =MIN(1,Cartera!$F$5*(1+Cartera!$G$5)^(I$3-1)*$C$10) -> 0.053079332 | J13: =MIN(1,Cartera!$F$5*(1+Cartera!$G$5)^(J$3-1)*$C$10) -> 0.058918058 | K13: =MIN(1,Cartera!$F$5*(1+Cartera!$G$5)^(K$3-1)*$C$10) -> 0.065399045 | ... AB13: =MIN(1,Cartera!$F$5*(1+Cartera!$G$5)^(AB$3-1)*$C$10) -> 0.38553343
B14: Supervivencia inicio | C14: LE estresada → | D14: =1 -> 1 | E14: =D18 -> 0.9685 | F14: =E18 -> 0.9346364 | G14: =F18 -> 0.89836208 | H14: =G18 -> 0.85966031 | I14: =H18 -> 0.81855202 | J14: =I18 -> 0.77510383 | K14: =J18 -> 0.72943622 | L14: =K18 -> 0.68173178 | ... AB14: =AA18 -> 0.02725588
B15: Muertes (fracción) | D15: =D14*D13 -> 0.0315 | E15: =E14*E13 -> 0.033863602 | F15: =F14*F13 -> 0.036274313 | G15: =G14*G13 -> 0.038701777 | H15: =H14*H13 -> 0.041108284 | I15: =I14*I13 -> 0.043448195 | J15: =J14*J13 -> 0.045667613 | K15: =K14*K13 -> 0.047704432 | ... AB15: =AB14*AB13 -> 0.010508053
B16: Beneficio por muerte bruto (USD mm) | D16: =D15*Cartera!$D$5 -> 2.835 | E16: =E15*Cartera!$D$5 -> 3.0477242 | F16: =F15*Cartera!$D$5 -> 3.2646882 | G16: =G15*Cartera!$D$5 -> 3.4831599 | H16: =H15*Cartera!$D$5 -> 3.6997455 | I16: =I15*Cartera!$D$5 -> 3.9103375 | J16: =J15*Cartera!$D$5 -> 4.1100851 | K16: =K15*Cartera!$D$5 -> 4.2933989 | ... AB16: =AB15*Cartera!$D$5 -> 0.94572476
B17: Primas pagadas (USD mm) | D17: =D14*Cartera!$D$5*Cartera!$H$5*(1+$C$8)^(D$3-1) -> 3.6 | E17: =E14*Cartera!$D$5*Cartera!$H$5*(1+$C$8)^(E$3-1) -> 3.556332 | F17: =F14*Cartera!$D$5*Cartera!$H$5*(1+$C$8)^(F$3-1) -> 3.5006245 | G17: =G14*Cartera!$D$5*Cartera!$H$5*(1+$C$8)^(G$3-1) -> 3.4320565 | H17: =H14*Cartera!$D$5*Cartera!$H$5*(1+$C$8)^(H$3-1) -> 3.3498863 | I17: =I14*Cartera!$D$5*Cartera!$H$5*(1+$C$8)^(I$3-1) -> 3.2534913 | J17: =J14*Cartera!$D$5*Cartera!$H$5*(1+$C$8)^(J$3-1) -> 3.1424141 | K17: =K14*Cartera!$D$5*Cartera!$H$5*(1+$C$8)^(K$3-1) -> 3.0164145 | ... AB17: =AB14*Cartera!$D$5*Cartera!$H$5*(1+$C$8)^(AB$3-1) -> 0.15782174
B18: Supervivencia fin | C18: =SUM(D18:AB18)+0.5 -> 11.681772 | D18: =D14-D15 -> 0.9685 | E18: =E14-E15 -> 0.9346364 | F18: =F14-F15 -> 0.89836208 | G18: =G14-G15 -> 0.85966031 | H18: =H14-H15 -> 0.81855202 | I18: =I14-I15 -> 0.77510383 | J18: =J14-J15 -> 0.72943622 | K18: =K14-K15 -> 0.68173178 | ... AB18: =AB14-AB15 -> 0.016747827
A20: =Cartera!A6&" – "&Cartera!B6 -> C2 – Edad 80–84, deterioro moderado
B21: q estresada | D21: =MIN(1,Cartera!$F$6*(1+Cartera!$G$6)^(D$3-1)*$C$10) -> 0.0455 | E21: =MIN(1,Cartera!$F$6*(1+Cartera!$G$6)^(E$3-1)*$C$10) -> 0.05005 | F21: =MIN(1,Cartera!$F$6*(1+Cartera!$G$6)^(F$3-1)*$C$10) -> 0.055055 | G21: =MIN(1,Cartera!$F$6*(1+Cartera!$G$6)^(G$3-1)*$C$10) -> 0.0605605 | H21: =MIN(1,Cartera!$F$6*(1+Cartera!$G$6)^(H$3-1)*$C$10) -> 0.06661655 | I21: =MIN(1,Cartera!$F$6*(1+Cartera!$G$6)^(I$3-1)*$C$10) -> 0.073278205 | J21: =MIN(1,Cartera!$F$6*(1+Cartera!$G$6)^(J$3-1)*$C$10) -> 0.080606025 | K21: =MIN(1,Cartera!$F$6*(1+Cartera!$G$6)^(K$3-1)*$C$10) -> 0.088666628 | ... AB21: =MIN(1,Cartera!$F$6*(1+Cartera!$G$6)^(AB$3-1)*$C$10) -> 0.44816284
B22: Supervivencia inicio | C22: LE estresada → | D22: =1 -> 1 | E22: =D26 -> 0.9545 | F22: =E26 -> 0.90672728 | G22: =F26 -> 0.8568074 | H22: =G26 -> 0.80491872 | I22: =H26 -> 0.75129781 | J22: =I26 -> 0.69624406 | K22: =J26 -> 0.64012259 | L22: =K26 -> 0.58336508 | ... AB22: =AA26 -> 0.0098460628
B23: Muertes (fracción) | D23: =D22*D21 -> 0.0455 | E23: =E22*E21 -> 0.047772725 | F23: =F22*F21 -> 0.04991987 | G23: =G22*G21 -> 0.051888685 | H23: =H22*H21 -> 0.053620908 | I23: =I22*I21 -> 0.055053755 | J23: =J22*J21 -> 0.056121466 | K23: =K22*K21 -> 0.056757512 | ... AB23: =AB22*AB21 -> 0.0044126394
B24: Beneficio por muerte bruto (USD mm) | D24: =D23*Cartera!$D$6 -> 5.46 | E24: =E23*Cartera!$D$6 -> 5.732727 | F24: =F23*Cartera!$D$6 -> 5.9903844 | G24: =G23*Cartera!$D$6 -> 6.2266422 | H24: =H23*Cartera!$D$6 -> 6.434509 | I24: =I23*Cartera!$D$6 -> 6.6064506 | J24: =J23*Cartera!$D$6 -> 6.7345759 | K24: =K23*Cartera!$D$6 -> 6.8109014 | ... AB24: =AB23*Cartera!$D$6 -> 0.52951673
B25: Primas pagadas (USD mm) | D25: =D22*Cartera!$D$6*Cartera!$H$6*(1+$C$8)^(D$3-1) -> 6 | E25: =E22*Cartera!$D$6*Cartera!$H$6*(1+$C$8)^(E$3-1) -> 5.84154 | F25: =F22*Cartera!$D$6*Cartera!$H$6*(1+$C$8)^(F$3-1) -> 5.6601543 | G25: =G22*Cartera!$D$6*Cartera!$H$6*(1+$C$8)^(G$3-1) -> 5.4555052 | H25: =H22*Cartera!$D$6*Cartera!$H$6*(1+$C$8)^(H$3-1) -> 5.2276195 | I25: =I22*Cartera!$D$6*Cartera!$H$6*(1+$C$8)^(I$3-1) -> 4.9769609 | J25: =J22*Cartera!$D$6*Cartera!$H$6*(1+$C$8)^(J$3-1) -> 4.7045033 | K25: =K22*Cartera!$D$6*Cartera!$H$6*(1+$C$8)^(K$3-1) -> 4.4117979 | ... AB25: =AB22*Cartera!$D$6*Cartera!$H$6*(1+$C$8)^(AB$3-1) -> 0.095020645
B26: Supervivencia fin | C26: =SUM(D26:AB26)+0.5 -> 9.9050249 | D26: =D22-D23 -> 0.9545 | E26: =E22-E23 -> 0.90672728 | F26: =F22-F23 -> 0.8568074 | G26: =G22-G23 -> 0.80491872 | H26: =H22-H23 -> 0.75129781 | I26: =I22-I23 -> 0.69624406 | J26: =J22-J23 -> 0.64012259 | K26: =K22-K23 -> 0.58336508 | ... AB26: =AB22-AB23 -> 0.0054334233
A28: =Cartera!A7&" – "&Cartera!B7 -> C3 – Edad 85–89, deterioro significativo
B29: q estresada | D29: =MIN(1,Cartera!$F$7*(1+Cartera!$G$7)^(D$3-1)*$C$10) -> 0.0665 | E29: =MIN(1,Cartera!$F$7*(1+Cartera!$G$7)^(E$3-1)*$C$10) -> 0.072485 | F29: =MIN(1,Cartera!$F$7*(1+Cartera!$G$7)^(F$3-1)*$C$10) -> 0.07900865 | G29: =MIN(1,Cartera!$F$7*(1+Cartera!$G$7)^(G$3-1)*$C$10) -> 0.086119428 | H29: =MIN(1,Cartera!$F$7*(1+Cartera!$G$7)^(H$3-1)*$C$10) -> 0.093870177 | I29: =MIN(1,Cartera!$F$7*(1+Cartera!$G$7)^(I$3-1)*$C$10) -> 0.10231849 | J29: =MIN(1,Cartera!$F$7*(1+Cartera!$G$7)^(J$3-1)*$C$10) -> 0.11152716 | K29: =MIN(1,Cartera!$F$7*(1+Cartera!$G$7)^(K$3-1)*$C$10) -> 0.1215646 | ... AB29: =MIN(1,Cartera!$F$7*(1+Cartera!$G$7)^(AB$3-1)*$C$10) -> 0.52608703
B30: Supervivencia inicio | C30: LE estresada → | D30: =1 -> 1 | E30: =D34 -> 0.9335 | F30: =E34 -> 0.86583525 | G30: =F34 -> 0.79742678 | H30: =G34 -> 0.72875284 | I30: =H34 -> 0.66034468 | J30: =I34 -> 0.59277921 | K30: =J34 -> 0.52666823 | L30: =K34 -> 0.46264402 | ... AB30: =AA34 -> 0.0023239352
B31: Muertes (fracción) | D31: =D30*D29 -> 0.0665 | E31: =E30*E29 -> 0.067664747 | F31: =F30*F29 -> 0.068408474 | G31: =G30*G29 -> 0.068673938 | H31: =H30*H29 -> 0.068408158 | I31: =I30*I29 -> 0.067565473 | J31: =J30*J29 -> 0.06611098 | K31: =K30*K29 -> 0.064024213 | ... AB31: =AB30*AB29 -> 0.0012225922
B32: Beneficio por muerte bruto (USD mm) | D32: =D31*Cartera!$D$7 -> 6.65 | E32: =E31*Cartera!$D$7 -> 6.7664748 | F32: =F31*Cartera!$D$7 -> 6.8408474 | G32: =G31*Cartera!$D$7 -> 6.8673938 | H32: =H31*Cartera!$D$7 -> 6.8408158 | I32: =I31*Cartera!$D$7 -> 6.7565473 | J32: =J31*Cartera!$D$7 -> 6.611098 | K32: =K31*Cartera!$D$7 -> 6.4024213 | ... AB32: =AB31*Cartera!$D$7 -> 0.12225922
B33: Primas pagadas (USD mm) | D33: =D30*Cartera!$D$7*Cartera!$H$7*(1+$C$8)^(D$3-1) -> 6 | E33: =E30*Cartera!$D$7*Cartera!$H$7*(1+$C$8)^(E$3-1) -> 5.71302 | F33: =F30*Cartera!$D$7*Cartera!$H$7*(1+$C$8)^(F$3-1) -> 5.40489 | G33: =G30*Cartera!$D$7*Cartera!$H$7*(1+$C$8)^(G$3-1) -> 5.0774141 | H33: =H30*Cartera!$D$7*Cartera!$H$7*(1+$C$8)^(H$3-1) -> 4.7329531 | I33: =I30*Cartera!$D$7*Cartera!$H$7*(1+$C$8)^(I$3-1) -> 4.3744433 | J33: =J30*Cartera!$D$7*Cartera!$H$7*(1+$C$8)^(J$3-1) -> 4.005394 | K33: =K30*Cartera!$D$7*Cartera!$H$7*(1+$C$8)^(K$3-1) -> 3.6298575 | ... AB33: =AB30*Cartera!$D$7*Cartera!$H$7*(1+$C$8)^(AB$3-1) -> 0.022427424
B34: Supervivencia fin | C34: =SUM(D34:AB34)+0.5 -> 8.1029851 | D34: =D30-D31 -> 0.9335 | E34: =E30-E31 -> 0.86583525 | F34: =F30-F31 -> 0.79742678 | G34: =G30-G31 -> 0.72875284 | H34: =H30-H31 -> 0.66034468 | I34: =I30-I31 -> 0.59277921 | J34: =J30-J31 -> 0.52666823 | K34: =K30-K31 -> 0.46264402 | ... AB34: =AB30-AB31 -> 0.001101343
A36: =Cartera!A8&" – "&Cartera!B8 -> C4 – Edad 90+, deterioro severo
B37: q estresada | D37: =MIN(1,Cartera!$F$8*(1+Cartera!$G$8)^(D$3-1)*$C$10) -> 0.098 | E37: =MIN(1,Cartera!$F$8*(1+Cartera!$G$8)^(E$3-1)*$C$10) -> 0.10584 | F37: =MIN(1,Cartera!$F$8*(1+Cartera!$G$8)^(F$3-1)*$C$10) -> 0.1143072 | G37: =MIN(1,Cartera!$F$8*(1+Cartera!$G$8)^(G$3-1)*$C$10) -> 0.12345178 | H37: =MIN(1,Cartera!$F$8*(1+Cartera!$G$8)^(H$3-1)*$C$10) -> 0.13332792 | I37: =MIN(1,Cartera!$F$8*(1+Cartera!$G$8)^(I$3-1)*$C$10) -> 0.14399415 | J37: =MIN(1,Cartera!$F$8*(1+Cartera!$G$8)^(J$3-1)*$C$10) -> 0.15551368 | K37: =MIN(1,Cartera!$F$8*(1+Cartera!$G$8)^(K$3-1)*$C$10) -> 0.16795478 | ... AB37: =MIN(1,Cartera!$F$8*(1+Cartera!$G$8)^(AB$3-1)*$C$10) -> 0.62143571
B38: Supervivencia inicio | C38: LE estresada → | D38: =1 -> 1 | E38: =D42 -> 0.902 | F38: =E42 -> 0.80653232 | G38: =F42 -> 0.71433987 | H38: =G42 -> 0.62615334 | I38: =H42 -> 0.54266962 | J38: =I42 -> 0.46452837 | K38: =J42 -> 0.39228785 | L38: =K42 -> 0.32640123 | ... AB38: =AA42 -> 0.00028759525
B39: Muertes (fracción) | D39: =D38*D37 -> 0.098 | E39: =E38*E37 -> 0.09546768 | F39: =F38*F37 -> 0.092192451 | G39: =G38*G37 -> 0.088186525 | H39: =H38*H37 -> 0.083483722 | I39: =I38*I37 -> 0.078141252 | J39: =J38*J37 -> 0.072240518 | K39: =K38*K37 -> 0.065886619 | ... AB39: =AB38*AB37 -> 0.00017872196
B40: Beneficio por muerte bruto (USD mm) | D40: =D39*Cartera!$D$8 -> 7.84 | E40: =E39*Cartera!$D$8 -> 7.6374144 | F40: =F39*Cartera!$D$8 -> 7.3753961 | G40: =G39*Cartera!$D$8 -> 7.054922 | H40: =H39*Cartera!$D$8 -> 6.6786977 | I40: =I39*Cartera!$D$8 -> 6.2513001 | J40: =J39*Cartera!$D$8 -> 5.7792414 | K40: =K39*Cartera!$D$8 -> 5.2709295 | ... AB40: =AB39*Cartera!$D$8 -> 0.014297757
B41: Primas pagadas (USD mm) | D41: =D38*Cartera!$D$8*Cartera!$H$8*(1+$C$8)^(D$3-1) -> 5.6 | E41: =E38*Cartera!$D$8*Cartera!$H$8*(1+$C$8)^(E$3-1) -> 5.152224 | F41: =F38*Cartera!$D$8*Cartera!$H$8*(1+$C$8)^(F$3-1) -> 4.6990509 | G41: =G38*Cartera!$D$8*Cartera!$H$8*(1+$C$8)^(G$3-1) -> 4.2451538 | H41: =H38*Cartera!$D$8*Cartera!$H$8*(1+$C$8)^(H$3-1) -> 3.7955037 | I41: =I38*Cartera!$D$8*Cartera!$H$8*(1+$C$8)^(I$3-1) -> 3.3552462 | J41: =J38*Cartera!$D$8*Cartera!$H$8*(1+$C$8)^(J$3-1) -> 2.9295526 | K41: =K38*Cartera!$D$8*Cartera!$H$8*(1+$C$8)^(K$3-1) -> 2.5234464 | ... AB41: =AB38*Cartera!$D$8*Cartera!$H$8*(1+$C$8)^(AB$3-1) -> 0.0025904419
B42: Supervivencia fin | C42: =SUM(D42:AB42)+0.5 -> 6.3728464 | D42: =D38-D39 -> 0.902 | E42: =E38-E39 -> 0.80653232 | F42: =F38-F39 -> 0.71433987 | G42: =G38-G39 -> 0.62615334 | H42: =H38-H39 -> 0.54266962 | I42: =I38-I39 -> 0.46452837 | J42: =J38-J39 -> 0.39228785 | K42: =K38-K39 -> 0.32640123 | ... AB42: =AB38-AB39 -> 0.00010887329
A44: =Cartera!A9&" – "&Cartera!B9 -> C5 – Edad 70–74, enfermedad crónica
B45: q estresada | D45: =MIN(1,Cartera!$F$9*(1+Cartera!$G$9)^(D$3-1)*$C$10) -> 0.035 | E45: =MIN(1,Cartera!$F$9*(1+Cartera!$G$9)^(E$3-1)*$C$10) -> 0.0392 | F45: =MIN(1,Cartera!$F$9*(1+Cartera!$G$9)^(F$3-1)*$C$10) -> 0.043904 | G45: =MIN(1,Cartera!$F$9*(1+Cartera!$G$9)^(G$3-1)*$C$10) -> 0.04917248 | H45: =MIN(1,Cartera!$F$9*(1+Cartera!$G$9)^(H$3-1)*$C$10) -> 0.055073178 | I45: =MIN(1,Cartera!$F$9*(1+Cartera!$G$9)^(I$3-1)*$C$10) -> 0.061681959 | J45: =MIN(1,Cartera!$F$9*(1+Cartera!$G$9)^(J$3-1)*$C$10) -> 0.069083794 | K45: =MIN(1,Cartera!$F$9*(1+Cartera!$G$9)^(K$3-1)*$C$10) -> 0.077373849 | ... AB45: =MIN(1,Cartera!$F$9*(1+Cartera!$G$9)^(AB$3-1)*$C$10) -> 0.53125201
B46: Supervivencia inicio | C46: LE estresada → | D46: =1 -> 1 | E46: =D50 -> 0.965 | F46: =E50 -> 0.927172 | G46: =F50 -> 0.88646544 | H46: =G50 -> 0.84287574 | I46: =H50 -> 0.79645589 | J46: =I50 -> 0.74732893 | K46: =J50 -> 0.69570061 | L46: =K50 -> 0.64187158 | ... AB46: =AA50 -> 0.0077266287
...

Sheet CF_aa
A1: Flujo de caja y cascada – escenario aa
A2: Escenario | C2: aa
A3: Año | D3: 1 | E3: 2 | F3: 3 | G3: 4 | H3: 5 | I3: 6 | J3: 7 | K3: 8 | L3: 9 | M3: 10 | N3: 11 | O3: 12 | P3: 13 | Q3: 14 | R3: 15 | S3: 16 | T3: 17 | U3: 18 | V3: 19 | W3: 20 | X3: 21 | Y3: 22 | Z3: 23 | AA3: 24 | AB3: 25
A5: Multiplicador de mortalidad | C5: =Supuestos!C25 -> 0.76
A6: Penalidad pool pequeño | C6: =Supuestos!D25 -> 0.04
A7: Pérdida default aseguradoras | C7: =Supuestos!E25 -> 0.045
A8: Aumento anual de primas | C8: =Supuestos!F25 -> 0.015
A9: Haircut valor remanente | C9: =Supuestos!G25 -> 0.4
A10: Multiplicador efectivo | C10: =MAX(0,C5-IF(Cartera!C10<Supuestos!C16,C6,0)) -> 0.76
A12: =Cartera!A5&" – "&Cartera!B5 -> C1 – Edad 75–79, salud estándar
B13: q estresada | D13: =MIN(1,Cartera!$F$5*(1+Cartera!$G$5)^(D$3-1)*$C$10) -> 0.0342 | E13: =MIN(1,Cartera!$F$5*(1+Cartera!$G$5)^(E$3-1)*$C$10) -> 0.037962 | F13: =MIN(1,Cartera!$F$5*(1+Cartera!$G$5)^(F$3-1)*$C$10) -> 0.04213782 | G13: =MIN(1,Cartera!$F$5*(1+Cartera!$G$5)^(G$3-1)*$C$10) -> 0.04677298 | H13: =MIN(1,Cartera!$F$5*(1+Cartera!$G$5)^(H$3-1)*$C$10) -> 0.051918008 | I13: =MIN(1,Cartera!$F$5*(1+Cartera!$G$5)^(I$3-1)*$C$10) -> 0.057628989 | J13: =MIN(1,Cartera!$F$5*(1+Cartera!$G$5)^(J$3-1)*$C$10) -> 0.063968178 | K13: =MIN(1,Cartera!$F$5*(1+Cartera!$G$5)^(K$3-1)*$C$10) -> 0.071004677 | ... AB13: =MIN(1,Cartera!$F$5*(1+Cartera!$G$5)^(AB$3-1)*$C$10) -> 0.41857916
B14: Supervivencia inicio | C14: LE estresada → | D14: =1 -> 1 | E14: =D18 -> 0.9658 | F14: =E18 -> 0.9291363 | G14: =F18 -> 0.88998452 | H14: =G18 -> 0.84835729 | I14: =H18 -> 0.80431227 | J14: =I18 -> 0.75796057 | K14: =J18 -> 0.70947521 | L14: =K18 -> 0.65909915 | ... AB14: =AA18 -> 0.01914405
B15: Muertes (fracción) | D15: =D14*D13 -> 0.0342 | E15: =E14*E13 -> 0.0366637 | F15: =F14*F13 -> 0.039151778 | G15: =G14*G13 -> 0.041627228 | H15: =H14*H13 -> 0.044045021 | I15: =I14*I13 -> 0.046351703 | J15: =J14*J13 -> 0.048485356 | K15: =K14*K13 -> 0.050376059 | ... AB15: =AB14*AB13 -> 0.0080133004
B16: Beneficio por muerte bruto (USD mm) | D16: =D15*Cartera!$D$5 -> 3.078 | E16: =E15*Cartera!$D$5 -> 3.299733 | F16: =F15*Cartera!$D$5 -> 3.52366 | G16: =G15*Cartera!$D$5 -> 3.7464506 | H16: =H15*Cartera!$D$5 -> 3.9640519 | I16: =I15*Cartera!$D$5 -> 4.1716533 | J16: =J15*Cartera!$D$5 -> 4.3636821 | K16: =K15*Cartera!$D$5 -> 4.5338453 | ... AB16: =AB15*Cartera!$D$5 -> 0.72119703
B17: Primas pagadas (USD mm) | D17: =D14*Cartera!$D$5*Cartera!$H$5*(1+$C$8)^(D$3-1) -> 3.6 | E17: =E14*Cartera!$D$5*Cartera!$H$5*(1+$C$8)^(E$3-1) -> 3.5290332 | F17: =F14*Cartera!$D$5*Cartera!$H$5*(1+$C$8)^(F$3-1) -> 3.44599 | G17: =G14*Cartera!$D$5*Cartera!$H$5*(1+$C$8)^(G$3-1) -> 3.3502952 | H17: =H14*Cartera!$D$5*Cartera!$H$5*(1+$C$8)^(H$3-1) -> 3.2414958 | I17: =I14*Cartera!$D$5*Cartera!$H$5*(1+$C$8)^(I$3-1) -> 3.1193019 | J17: =J14*Cartera!$D$5*Cartera!$H$5*(1+$C$8)^(J$3-1) -> 2.9836328 | K17: =K14*Cartera!$D$5*Cartera!$H$5*(1+$C$8)^(K$3-1) -> 2.8346668 | ... AB17: =AB14*Cartera!$D$5*Cartera!$H$5*(1+$C$8)^(AB$3-1) -> 0.098519305
B18: Supervivencia fin | C18: =SUM(D18:AB18)+0.5 -> 11.187024 | D18: =D14-D15 -> 0.9658 | E18: =E14-E15 -> 0.9291363 | F18: =F14-F15 -> 0.88998452 | G18: =G14-G15 -> 0.84835729 | H18: =H14-H15 -> 0.80431227 | I18: =I14-I15 -> 0.75796057 | J18: =J14-J15 -> 0.70947521 | K18: =K14-K15 -> 0.65909915 | ... AB18: =AB14-AB15 -> 0.01113075
A20: =Cartera!A6&" – "&Cartera!B6 -> C2 – Edad 80–84, deterioro moderado
B21: q estresada | D21: =MIN(1,Cartera!$F$6*(1+Cartera!$G$6)^(D$3-1)*$C$10) -> 0.0494 | E21: =MIN(1,Cartera!$F$6*(1+Cartera!$G$6)^(E$3-1)*$C$10) -> 0.05434 | F21: =MIN(1,Cartera!$F$6*(1+Cartera!$G$6)^(F$3-1)*$C$10) -> 0.059774 | G21: =MIN(1,Cartera!$F$6*(1+Cartera!$G$6)^(G$3-1)*$C$10) -> 0.0657514 | H21: =MIN(1,Cartera!$F$6*(1+Cartera!$G$6)^(H$3-1)*$C$10) -> 0.07232654 | I21: =MIN(1,Cartera!$F$6*(1+Cartera!$G$6)^(I$3-1)*$C$10) -> 0.079559194 | J21: =MIN(1,Cartera!$F$6*(1+Cartera!$G$6)^(J$3-1)*$C$10) -> 0.087515113 | K21: =MIN(1,Cartera!$F$6*(1+Cartera!$G$6)^(K$3-1)*$C$10) -> 0.096266625 | ... AB21: =MIN(1,Cartera!$F$6*(1+Cartera!$G$6)^(AB$3-1)*$C$10) -> 0.48657679
B22: Supervivencia inicio | C22: LE estresada → | D22: =1 -> 1 | E22: =D26 -> 0.9506 | F22: =E26 -> 0.8989444 | G22: =F26 -> 0.84521089 | H22: =G26 -> 0.78963709 | I22: =H26 -> 0.73252538 | J22: =I26 -> 0.67424625 | K22: =J26 -> 0.61523951 | L22: =K26 -> 0.55601248 | ... AB22: =AA26 -> 0.0061637755
B23: Muertes (fracción) | D23: =D22*D21 -> 0.0494 | E23: =E22*E21 -> 0.051655604 | F23: =F22*F21 -> 0.053733502 | G23: =G22*G21 -> 0.0555738 | H23: =H22*H21 -> 0.057111719 | I23: =I22*I21 -> 0.058279128 | J23: =J22*J21 -> 0.059006737 | K23: =K22*K21 -> 0.059227031 | ... AB23: =AB22*AB21 -> 0.0029991501
B24: Beneficio por muerte bruto (USD mm) | D24: =D23*Cartera!$D$6 -> 5.928 | E24: =E23*Cartera!$D$6 -> 6.1986725 | F24: =F23*Cartera!$D$6 -> 6.4480203 | G24: =G23*Cartera!$D$6 -> 6.6688559 | H24: =H23*Cartera!$D$6 -> 6.8534063 | I24: =I23*Cartera!$D$6 -> 6.9934954 | J24: =J23*Cartera!$D$6 -> 7.0808084 | K24: =K23*Cartera!$D$6 -> 7.1072437 | ... AB24: =AB23*Cartera!$D$6 -> 0.35989802
B25: Primas pagadas (USD mm) | D25: =D22*Cartera!$D$6*Cartera!$H$6*(1+$C$8)^(D$3-1) -> 6 | E25: =E22*Cartera!$D$6*Cartera!$H$6*(1+$C$8)^(E$3-1) -> 5.789154 | F25: =F22*Cartera!$D$6*Cartera!$H$6*(1+$C$8)^(F$3-1) -> 5.5566899 | G25: =G22*Cartera!$D$6*Cartera!$H$6*(1+$C$8)^(G$3-1) -> 5.3029125 | H25: =H22*Cartera!$D$6*Cartera!$H$6*(1+$C$8)^(H$3-1) -> 5.0285522 | I25: =I22*Cartera!$D$6*Cartera!$H$6*(1+$C$8)^(I$3-1) -> 4.7348272 | J25: =J22*Cartera!$D$6*Cartera!$H$6*(1+$C$8)^(J$3-1) -> 4.4235001 | K25: =K22*Cartera!$D$6*Cartera!$H$6*(1+$C$8)^(K$3-1) -> 4.0969226 | ... AB25: =AB22*Cartera!$D$6*Cartera!$H$6*(1+$C$8)^(AB$3-1) -> 0.052866807
B26: Supervivencia fin | C26: =SUM(D26:AB26)+0.5 -> 9.4305352 | D26: =D22-D23 -> 0.9506 | E26: =E22-E23 -> 0.8989444 | F26: =F22-F23 -> 0.84521089 | G26: =G22-G23 -> 0.78963709 | H26: =H22-H23 -> 0.73252538 | I26: =I22-I23 -> 0.67424625 | J26: =J22-J23 -> 0.61523951 | K26: =K22-K23 -> 0.55601248 | ... AB26: =AB22-AB23 -> 0.0031646254
A28: =Cartera!A7&" – "&Cartera!B7 -> C3 – Edad 85–89, deterioro significativo
B29: q estresada | D29: =MIN(1,Cartera!$F$7*(1+Cartera!$G$7)^(D$3-1)*$C$10) -> 0.0722 | E29: =MIN(1,Cartera!$F$7*(1+Cartera!$G$7)^(E$3-1)*$C$10) -> 0.078698 | F29: =MIN(1,Cartera!$F$7*(1+Cartera!$G$7)^(F$3-1)*$C$10) -> 0.08578082 | G29: =MIN(1,Cartera!$F$7*(1+Cartera!$G$7)^(G$3-1)*$C$10) -> 0.093501094 | H29: =MIN(1,Cartera!$F$7*(1+Cartera!$G$7)^(H$3-1)*$C$10) -> 0.10191619 | I29: =MIN(1,Cartera!$F$7*(1+Cartera!$G$7)^(I$3-1)*$C$10) -> 0.11108865 | J29: =MIN(1,Cartera!$F$7*(1+Cartera!$G$7)^(J$3-1)*$C$10) -> 0.12108663 | K29: =MIN(1,Cartera!$F$7*(1+Cartera!$G$7)^(K$3-1)*$C$10) -> 0.13198442 | ... AB29: =MIN(1,Cartera!$F$7*(1+Cartera!$G$7)^(AB$3-1)*$C$10) -> 0.57118021
B30: Supervivencia inicio | C30: LE estresada → | D30: =1 -> 1 | E30: =D34 -> 0.9278 | F30: =E34 -> 0.854784 | G30: =F34 -> 0.78145992 | H30: =G34 -> 0.70839257 | I30: =H34 -> 0.63619589 | J30: =I34 -> 0.56552175 | K30: =J34 -> 0.49704463 | L30: =K34 -> 0.43144248 | ... AB30: =AA34 -> 0.0012193811
B31: Muertes (fracción) | D31: =D30*D29 -> 0.0722 | E31: =E30*E29 -> 0.073016004 | F31: =F30*F29 -> 0.073324072 | G31: =G30*G29 -> 0.073067358 | H31: =H30*H29 -> 0.072196673 | I31: =I30*I29 -> 0.070674143 | J31: =J30*J29 -> 0.068477122 | K31: =K30*K29 -> 0.065602149 | ... AB31: =AB30*AB29 -> 0.00069648635
B32: Beneficio por muerte bruto (USD mm) | D32: =D31*Cartera!$D$7 -> 7.22 | E32: =E31*Cartera!$D$7 -> 7.3016004 | F32: =F31*Cartera!$D$7 -> 7.3324072 | G32: =G31*Cartera!$D$7 -> 7.3067358 | H32: =H31*Cartera!$D$7 -> 7.2196673 | I32: =I31*Cartera!$D$7 -> 7.0674143 | J32: =J31*Cartera!$D$7 -> 6.8477122 | K32: =K31*Cartera!$D$7 -> 6.5602149 | ... AB32: =AB31*Cartera!$D$7 -> 0.069648635
B33: Primas pagadas (USD mm) | D33: =D30*Cartera!$D$7*Cartera!$H$7*(1+$C$8)^(D$3-1) -> 6 | E33: =E30*Cartera!$D$7*Cartera!$H$7*(1+$C$8)^(E$3-1) -> 5.650302 | F33: =F30*Cartera!$D$7*Cartera!$H$7*(1+$C$8)^(F$3-1) -> 5.2837191 | G33: =G30*Cartera!$D$7*Cartera!$H$7*(1+$C$8)^(G$3-1) -> 4.9029345 | H33: =H30*Cartera!$D$7*Cartera!$H$7*(1+$C$8)^(H$3-1) -> 4.5111723 | I33: =I30*Cartera!$D$7*Cartera!$H$7*(1+$C$8)^(I$3-1) -> 4.112182 | J33: =J30*Cartera!$D$7*Cartera!$H$7*(1+$C$8)^(J$3-1) -> 3.7101957 | K33: =K30*Cartera!$D$7*Cartera!$H$7*(1+$C$8)^(K$3-1) -> 3.3098547 | ... AB33: =AB30*Cartera!$D$7*Cartera!$H$7*(1+$C$8)^(AB$3-1) -> 0.010458652
B34: Supervivencia fin | C34: =SUM(D34:AB34)+0.5 -> 7.6656782 | D34: =D30-D31 -> 0.9278 | E34: =E30-E31 -> 0.854784 | F34: =F30-F31 -> 0.78145992 | G34: =G30-G31 -> 0.70839257 | H34: =H30-H31 -> 0.63619589 | I34: =I30-I31 -> 0.56552175 | J34: =J30-J31 -> 0.49704463 | K34: =K30-K31 -> 0.43144248 | ... AB34: =AB30-AB31 -> 0.00052289476
A36: =Cartera!A8&" – "&Cartera!B8 -> C4 – Edad 90+, deterioro severo
B37: q estresada | D37: =MIN(1,Cartera!$F$8*(1+Cartera!$G$8)^(D$3-1)*$C$10) -> 0.1064 | E37: =MIN(1,Cartera!$F$8*(1+Cartera!$G$8)^(E$3-1)*$C$10) -> 0.114912 | F37: =MIN(1,Cartera!$F$8*(1+Cartera!$G$8)^(F$3-1)*$C$10) -> 0.12410496 | G37: =MIN(1,Cartera!$F$8*(1+Cartera!$G$8)^(G$3-1)*$C$10) -> 0.13403336 | H37: =MIN(1,Cartera!$F$8*(1+Cartera!$G$8)^(H$3-1)*$C$10) -> 0.14475603 | I37: =MIN(1,Cartera!$F$8*(1+Cartera!$G$8)^(I$3-1)*$C$10) -> 0.15633651 | J37: =MIN(1,Cartera!$F$8*(1+Cartera!$G$8)^(J$3-1)*$C$10) -> 0.16884343 | K37: =MIN(1,Cartera!$F$8*(1+Cartera!$G$8)^(K$3-1)*$C$10) -> 0.1823509 | ... AB37: =MIN(1,Cartera!$F$8*(1+Cartera!$G$8)^(AB$3-1)*$C$10) -> 0.67470163
B38: Supervivencia inicio | C38: LE estresada → | D38: =1 -> 1 | E38: =D42 -> 0.8936 | F38: =E42 -> 0.79091464 | G38: =F42 -> 0.69275821 | H38: =G42 -> 0.5999055 | I38: =H42 -> 0.51306556 | J38: =I42 -> 0.43285469 | K38: =J42 -> 0.35977002 | L38: =K42 -> 0.29416563 | ... AB38: =AA42 -> 0.00011321584
B39: Muertes (fracción) | D39: =D38*D37 -> 0.1064 | E39: =E38*E37 -> 0.10268536 | F39: =F38*F37 -> 0.098156429 | G39: =G38*G37 -> 0.092852708 | H39: =H38*H37 -> 0.086839936 | I39: =I38*I37 -> 0.080210878 | J39: =J38*J37 -> 0.073084669 | K39: =K38*K37 -> 0.065604387 | ... AB39: =AB38*AB37 -> 7.6386909e-05
B40: Beneficio por muerte bruto (USD mm) | D40: =D39*Cartera!$D$8 -> 8.512 | E40: =E39*Cartera!$D$8 -> 8.2148291 | F40: =F39*Cartera!$D$8 -> 7.8525143 | G40: =G39*Cartera!$D$8 -> 7.4282166 | H40: =H39*Cartera!$D$8 -> 6.9471949 | I40: =I39*Cartera!$D$8 -> 6.4168703 | J40: =J39*Cartera!$D$8 -> 5.8467735 | K40: =K39*Cartera!$D$8 -> 5.248351 | ... AB40: =AB39*Cartera!$D$8 -> 0.0061109527
B41: Primas pagadas (USD mm) | D41: =D38*Cartera!$D$8*Cartera!$H$8*(1+$C$8)^(D$3-1) -> 5.6 | E41: =E38*Cartera!$D$8*Cartera!$H$8*(1+$C$8)^(E$3-1) -> 5.0792224 | F41: =F38*Cartera!$D$8*Cartera!$H$8*(1+$C$8)^(F$3-1) -> 4.5629922 | G41: =G38*Cartera!$D$8*Cartera!$H$8*(1+$C$8)^(G$3-1) -> 4.0566527 | H41: =H38*Cartera!$D$8*Cartera!$H$8*(1+$C$8)^(H$3-1) -> 3.5656199 | I41: =I38*Cartera!$D$8*Cartera!$H$8*(1+$C$8)^(I$3-1) -> 3.095217 | J41: =J38*Cartera!$D$8*Cartera!$H$8*(1+$C$8)^(J$3-1) -> 2.6504914 | K41: =K38*Cartera!$D$8*Cartera!$H$8*(1+$C$8)^(K$3-1) -> 2.236018 | ... AB41: =AB38*Cartera!$D$8*Cartera!$H$8*(1+$C$8)^(AB$3-1) -> 0.00090631719
B42: Supervivencia fin | C42: =SUM(D42:AB42)+0.5 -> 5.9866647 | D42: =D38-D39 -> 0.8936 | E42: =E38-E39 -> 0.79091464 | F42: =F38-F39 -> 0.69275821 | G42: =G38-G39 -> 0.5999055 | H42: =H38-H39 -> 0.51306556 | I42: =I38-I39 -> 0.43285469 | J42: =J38-J39 -> 0.35977002 | K42: =K38-K39 -> 0.29416563 | ... AB42: =AB38-AB39 -> 3.6828927e-05
A44: =Cartera!A9&" – "&Cartera!B9 -> C5 – Edad 70–74, enfermedad crónica
B45: q estresada | D45: =MIN(1,Cartera!$F$9*(1+Cartera!$G$9)^(D$3-1)*$C$10) -> 0.038 | E45: =MIN(1,Cartera!$F$9*(1+Cartera!$G$9)^(E$3-1)*$C$10) -> 0.04256 | F45: =MIN(1,Cartera!$F$9*(1+Cartera!$G$9)^(F$3-1)*$C$10) -> 0.0476672 | G45: =MIN(1,Cartera!$F$9*(1+Cartera!$G$9)^(G$3-1)*$C$10) -> 0.053387264 | H45: =MIN(1,Cartera!$F$9*(1+Cartera!$G$9)^(H$3-1)*$C$10) -> 0.059793736 | I45: =MIN(1,Cartera!$F$9*(1+Cartera!$G$9)^(I$3-1)*$C$10) -> 0.066968984 | J45: =MIN(1,Cartera!$F$9*(1+Cartera!$G$9)^(J$3-1)*$C$10) -> 0.075005262 | K45: =MIN(1,Cartera!$F$9*(1+Cartera!$G$9)^(K$3-1)*$C$10) -> 0.084005893 | ... AB45: =MIN(1,Cartera!$F$9*(1+Cartera!$G$9)^(AB$3-1)*$C$10) -> 0.5767879
B46: Supervivencia inicio | C46: LE estresada → | D46: =1 -> 1 | E46: =D50 -> 0.962 | F46: =E50 -> 0.92105728 | G46: =F50 -> 0.87715306 | H46: =G50 -> 0.83032426 | I46: =H50 -> 0.78067607 | J46: =I50 -> 0.72839498 | K46: =J50 -> 0.67376153 | L46: =K50 -> 0.61716159 | ... AB46: =AA50 -> 0.004633373
...

Sheet CF_a
A1: Flujo de caja y cascada – escenario a
A2: Escenario | C2: a
A3: Año | D3: 1 | E3: 2 | F3: 3 | G3: 4 | H3: 5 | I3: 6 | J3: 7 | K3: 8 | L3: 9 | M3: 10 | N3: 11 | O3: 12 | P3: 13 | Q3: 14 | R3: 15 | S3: 16 | T3: 17 | U3: 18 | V3: 19 | W3: 20 | X3: 21 | Y3: 22 | Z3: 23 | AA3: 24 | AB3: 25
A5: Multiplicador de mortalidad | C5: =Supuestos!C26 -> 0.82
A6: Penalidad pool pequeño | C6: =Supuestos!D26 -> 0.03
A7: Pérdida default aseguradoras | C7: =Supuestos!E26 -> 0.03
A8: Aumento anual de primas | C8: =Supuestos!F26 -> 0.01
A9: Haircut valor remanente | C9: =Supuestos!G26 -> 0.3
A10: Multiplicador efectivo | C10: =MAX(0,C5-IF(Cartera!C10<Supuestos!C16,C6,0)) -> 0.82
A12: =Cartera!A5&" – "&Cartera!B5 -> C1 – Edad 75–79, salud estándar
B13: q estresada | D13: =MIN(1,Cartera!$F$5*(1+Cartera!$G$5)^(D$3-1)*$C$10) -> 0.0369 | E13: =MIN(1,Cartera!$F$5*(1+Cartera!$G$5)^(E$3-1)*$C$10) -> 0.040959 | F13: =MIN(1,Cartera!$F$5*(1+Cartera!$G$5)^(F$3-1)*$C$10) -> 0.04546449 | G13: =MIN(1,Cartera!$F$5*(1+Cartera!$G$5)^(G$3-1)*$C$10) -> 0.050465584 | H13: =MIN(1,Cartera!$F$5*(1+Cartera!$G$5)^(H$3-1)*$C$10) -> 0.056016798 | I13: =MIN(1,Cartera!$F$5*(1+Cartera!$G$5)^(I$3-1)*$C$10) -> 0.062178646 | J13: =MIN(1,Cartera!$F$5*(1+Cartera!$G$5)^(J$3-1)*$C$10) -> 0.069018297 | K13: =MIN(1,Cartera!$F$5*(1+Cartera!$G$5)^(K$3-1)*$C$10) -> 0.07661031 | ... AB13: =MIN(1,Cartera!$F$5*(1+Cartera!$G$5)^(AB$3-1)*$C$10) -> 0.45162488
B14: Supervivencia inicio | C14: LE estresada → | D14: =1 -> 1 | E14: =D18 -> 0.9631 | F14: =E18 -> 0.92365239 | G14: =F18 -> 0.881659 | H14: =G18 -> 0.83716557 | I14: =H18 -> 0.79027023 | J14: =I18 -> 0.7411323 | K14: =J18 -> 0.68998061 | L14: =K18 -> 0.63712098 | ... AB14: =AA18 -> 0.013325124
B15: Muertes (fracción) | D15: =D14*D13 -> 0.0369 | E15: =E14*E13 -> 0.039447613 | F15: =F14*F13 -> 0.041993385 | G15: =G14*G13 -> 0.044493436 | H15: =H14*H13 -> 0.046895335 | I15: =I14*I13 -> 0.049137933 | J15: =J14*J13 -> 0.051151689 | K15: =K14*K13 -> 0.052859628 | ... AB15: =AB14*AB13 -> 0.0060179575
B16: Beneficio por muerte bruto (USD mm) | D16: =D15*Cartera!$D$5 -> 3.321 | E16: =E15*Cartera!$D$5 -> 3.5502852 | F16: =F15*Cartera!$D$5 -> 3.7794046 | G16: =G15*Cartera!$D$5 -> 4.0044093 | H16: =H15*Cartera!$D$5 -> 4.2205801 | I16: =I15*Cartera!$D$5 -> 4.422414 | J16: =J15*Cartera!$D$5 -> 4.603652 | K16: =K15*Cartera!$D$5 -> 4.7573665 | ... AB16: =AB15*Cartera!$D$5 -> 0.54161618
B17: Primas pagadas (USD mm) | D17: =D14*Cartera!$D$5*Cartera!$H$5*(1+$C$8)^(D$3-1) -> 3.6 | E17: =E14*Cartera!$D$5*Cartera!$H$5*(1+$C$8)^(E$3-1) -> 3.5018316 | F17: =F14*Cartera!$D$5*Cartera!$H$5*(1+$C$8)^(F$3-1) -> 3.3919841 | G17: =G14*Cartera!$D$5*Cartera!$H$5*(1+$C$8)^(G$3-1) -> 3.2701469 | H17: =H14*Cartera!$D$5*Cartera!$H$5*(1+$C$8)^(H$3-1) -> 3.1361682 | I17: =I14*Cartera!$D$5*Cartera!$H$5*(1+$C$8)^(I$3-1) -> 2.990095 | J17: =J14*Cartera!$D$5*Cartera!$H$5*(1+$C$8)^(J$3-1) -> 2.8322167 | K17: =K14*Cartera!$D$5*Cartera!$H$5*(1+$C$8)^(K$3-1) -> 2.6631094 | ... AB17: =AB14*Cartera!$D$5*Cartera!$H$5*(1+$C$8)^(AB$3-1) -> 0.060909738
B18: Supervivencia fin | C18: =SUM(D18:AB18)+0.5 -> 10.737455 | D18: =D14-D15 -> 0.9631 | E18: =E14-E15 -> 0.92365239 | F18: =F14-F15 -> 0.881659 | G18: =G14-G15 -> 0.83716557 | H18: =H14-H15 -> 0.79027023 | I18: =I14-I15 -> 0.7411323 | J18: =J14-J15 -> 0.68998061 | K18: =K14-K15 -> 0.63712098 | ... AB18: =AB14-AB15 -> 0.0073071665
A20: =Cartera!A6&" – "&Cartera!B6 -> C2 – Edad 80–84, deterioro moderado
B21: q estresada | D21: =MIN(1,Cartera!$F$6*(1+Cartera!$G$6)^(D$3-1)*$C$10) -> 0.0533 | E21: =MIN(1,Cartera!$F$6*(1+Cartera!$G$6)^(E$3-1)*$C$10) -> 0.05863 | F21: =MIN(1,Cartera!$F$6*(1+Cartera!$G$6)^(F$3-1)*$C$10) -> 0.064493 | G21: =MIN(1,Cartera!$F$6*(1+Cartera!$G$6)^(G$3-1)*$C$10) -> 0.0709423 | H21: =MIN(1,Cartera!$F$6*(1+Cartera!$G$6)^(H$3-1)*$C$10) -> 0.07803653 | I21: =MIN(1,Cartera!$F$6*(1+Cartera!$G$6)^(I$3-1)*$C$10) -> 0.085840183 | J21: =MIN(1,Cartera!$F$6*(1+Cartera!$G$6)^(J$3-1)*$C$10) -> 0.094424201 | K21: =MIN(1,Cartera!$F$6*(1+Cartera!$G$6)^(K$3-1)*$C$10) -> 0.10386662 | ... AB21: =MIN(1,Cartera!$F$6*(1+Cartera!$G$6)^(AB$3-1)*$C$10) -> 0.52499075
B22: Supervivencia inicio | C22: LE estresada → | D22: =1 -> 1 | E22: =D26 -> 0.9467 | F22: =E26 -> 0.89119498 | G22: =F26 -> 0.83371914 | H22: =G26 -> 0.77457319 | I22: =H26 -> 0.71412818 | J22: =I26 -> 0.65282729 | K22: =J26 -> 0.59118459 | L22: =K26 -> 0.52978025 | ... AB22: =AA26 -> 0.0037985334
B23: Muertes (fracción) | D23: =D22*D21 -> 0.0533 | E23: =E22*E21 -> 0.055505021 | F23: =F22*F21 -> 0.057475838 | G23: =G22*G21 -> 0.059145953 | H23: =H22*H21 -> 0.060445004 | I23: =I22*I21 -> 0.061300894 | J23: =J22*J21 -> 0.061642695 | K23: =K22*K21 -> 0.061404346 | ... AB23: =AB22*AB21 -> 0.0019941949
B24: Beneficio por muerte bruto (USD mm) | D24: =D23*Cartera!$D$6 -> 6.396 | E24: =E23*Cartera!$D$6 -> 6.6606025 | F24: =F23*Cartera!$D$6 -> 6.8971005 | G24: =G23*Cartera!$D$6 -> 7.0975144 | H24: =H23*Cartera!$D$6 -> 7.2534005 | I24: =I23*Cartera!$D$6 -> 7.3561073 | J24: =J23*Cartera!$D$6 -> 7.3971235 | K24: =K23*Cartera!$D$6 -> 7.3685216 | ... AB24: =AB23*Cartera!$D$6 -> 0.23930339
B25: Primas pagadas (USD mm) | D25: =D22*Cartera!$D$6*Cartera!$H$6*(1+$C$8)^(D$3-1) -> 6 | E25: =E22*Cartera!$D$6*Cartera!$H$6*(1+$C$8)^(E$3-1) -> 5.737002 | F25: =F22*Cartera!$D$6*Cartera!$H$6*(1+$C$8)^(F$3-1) -> 5.454648 | G25: =G22*Cartera!$D$6*Cartera!$H$6*(1+$C$8)^(G$3-1) -> 5.15389 | H25: =H22*Cartera!$D$6*Cartera!$H$6*(1+$C$8)^(H$3-1) -> 4.8361438 | I25: =I22*Cartera!$D$6*Cartera!$H$6*(1+$C$8)^(I$3-1) -> 4.5033354 | J25: =J22*Cartera!$D$6*Cartera!$H$6*(1+$C$8)^(J$3-1) -> 4.1579359 | K25: =K22*Cartera!$D$6*Cartera!$H$6*(1+$C$8)^(K$3-1) -> 3.8029794 | ... AB25: =AB22*Cartera!$D$6*Cartera!$H$6*(1+$C$8)^(AB$3-1) -> 0.028938777
B26: Supervivencia fin | C26: =SUM(D26:AB26)+0.5 -> 9.0031274 | D26: =D22-D23 -> 0.9467 | E26: =E22-E23 -> 0.89119498 | F26: =F22-F23 -> 0.83371914 | G26: =G22-G23 -> 0.77457319 | H26: =H22-H23 -> 0.71412818 | I26: =I22-I23 -> 0.65282729 | J26: =J22-J23 -> 0.59118459 | K26: =K22-K23 -> 0.52978025 | ... AB26: =AB22-AB23 -> 0.0018043385
A28: =Cartera!A7&" – "&Cartera!B7 -> C3 – Edad 85–89, deterioro significativo
B29: q estresada | D29: =MIN(1,Cartera!$F$7*(1+Cartera!$G$7)^(D$3-1)*$C$10) -> 0.0779 | E29: =MIN(1,Cartera!$F$7*(1+Cartera!$G$7)^(E$3-1)*$C$10) -> 0.084911 | F29: =MIN(1,Cartera!$F$7*(1+Cartera!$G$7)^(F$3-1)*$C$10) -> 0.09255299 | G29: =MIN(1,Cartera!$F$7*(1+Cartera!$G$7)^(G$3-1)*$C$10) -> 0.10088276 | H29: =MIN(1,Cartera!$F$7*(1+Cartera!$G$7)^(H$3-1)*$C$10) -> 0.10996221 | I29: =MIN(1,Cartera!$F$7*(1+Cartera!$G$7)^(I$3-1)*$C$10) -> 0.11985881 | J29: =MIN(1,Cartera!$F$7*(1+Cartera!$G$7)^(J$3-1)*$C$10) -> 0.1306461 | K29: =MIN(1,Cartera!$F$7*(1+Cartera!$G$7)^(K$3-1)*$C$10) -> 0.14240425 | ... AB29: =MIN(1,Cartera!$F$7*(1+Cartera!$G$7)^(AB$3-1)*$C$10) -> 0.61627338
B30: Supervivencia inicio | C30: LE estresada → | D30: =1 -> 1 | E30: =D34 -> 0.9221 | F30: =E34 -> 0.84380357 | G30: =F34 -> 0.76570702 | H30: =G34 -> 0.68846039 | I30: =H34 -> 0.61275576 | J30: =I34 -> 0.53931159 | K30: =J34 -> 0.46885263 | L30: =K34 -> 0.40208603 | ... AB30: =AA34 -> 0.0006210267
B31: Muertes (fracción) | D31: =D30*D29 -> 0.0779 | E31: =E30*E29 -> 0.078296433 | F31: =F30*F29 -> 0.078096543 | G31: =G30*G29 -> 0.077246637 | H31: =H30*H29 -> 0.075704624 | I31: =I30*I29 -> 0.073444174 | J31: =J30*J29 -> 0.070458955 | K31: =K30*K29 -> 0.066766606 | ... AB31: =AB30*AB29 -> 0.00038272222
B32: Beneficio por muerte bruto (USD mm) | D32: =D31*Cartera!$D$7 -> 7.79 | E32: =E31*Cartera!$D$7 -> 7.8296433 | F32: =F31*Cartera!$D$7 -> 7.8096543 | G32: =G31*Cartera!$D$7 -> 7.7246637 | H32: =H31*Cartera!$D$7 -> 7.5704624 | I32: =I31*Cartera!$D$7 -> 7.3444174 | J32: =J31*Cartera!$D$7 -> 7.0458955 | K32: =K31*Cartera!$D$7 -> 6.6766606 | ... AB32: =AB31*Cartera!$D$7 -> 0.038272222
B33: Primas pagadas (USD mm) | D33: =D30*Cartera!$D$7*Cartera!$H$7*(1+$C$8)^(D$3-1) -> 6 | E33: =E30*Cartera!$D$7*Cartera!$H$7*(1+$C$8)^(E$3-1) -> 5.587926 | F33: =F30*Cartera!$D$7*Cartera!$H$7*(1+$C$8)^(F$3-1) -> 5.1645841 | G33: =G30*Cartera!$D$7*Cartera!$H$7*(1+$C$8)^(G$3-1) -> 4.7334523 | H33: =H30*Cartera!$D$7*Cartera!$H$7*(1+$C$8)^(H$3-1) -> 4.2984878 | I33: =I30*Cartera!$D$7*Cartera!$H$7*(1+$C$8)^(I$3-1) -> 3.8640748 | J33: =J30*Cartera!$D$7*Cartera!$H$7*(1+$C$8)^(J$3-1) -> 3.4349407 | K33: =K30*Cartera!$D$7*Cartera!$H$7*(1+$C$8)^(K$3-1) -> 3.0160409 | ... AB33: =AB30*Cartera!$D$7*Cartera!$H$7*(1+$C$8)^(AB$3-1) -> 0.0047312347
B34: Supervivencia fin | C34: =SUM(D34:AB34)+0.5 -> 7.2749429 | D34: =D30-D31 -> 0.9221 | E34: =E30-E31 -> 0.84380357 | F34: =F30-F31 -> 0.76570702 | G34: =G30-G31 -> 0.68846039 | H34: =H30-H31 -> 0.61275576 | I34: =I30-I31 -> 0.53931159 | J34: =J30-J31 -> 0.46885263 | K34: =K30-K31 -> 0.40208603 | ... AB34: =AB30-AB31 -> 0.00023830448
A36: =Cartera!A8&" – "&Cartera!B8 -> C4 – Edad 90+, deterioro severo
B37: q estresada | D37: =MIN(1,Cartera!$F$8*(1+Cartera!$G$8)^(D$3-1)*$C$10) -> 0.1148 | E37: =MIN(1,Cartera!$F$8*(1+Cartera!$G$8)^(E$3-1)*$C$10) -> 0.123984 | F37: =MIN(1,Cartera!$F$8*(1+Cartera!$G$8)^(F$3-1)*$C$10) -> 0.13390272 | G37: =MIN(1,Cartera!$F$8*(1+Cartera!$G$8)^(G$3-1)*$C$10) -> 0.14461494 | H37: =MIN(1,Cartera!$F$8*(1+Cartera!$G$8)^(H$3-1)*$C$10) -> 0.15618413 | I37: =MIN(1,Cartera!$F$8*(1+Cartera!$G$8)^(I$3-1)*$C$10) -> 0.16867886 | J37: =MIN(1,Cartera!$F$8*(1+Cartera!$G$8)^(J$3-1)*$C$10) -> 0.18217317 | K37: =MIN(1,Cartera!$F$8*(1+Cartera!$G$8)^(K$3-1)*$C$10) -> 0.19674703 | ... AB37: =MIN(1,Cartera!$F$8*(1+Cartera!$G$8)^(AB$3-1)*$C$10) -> 0.72796755
B38: Supervivencia inicio | C38: LE estresada → | D38: =1 -> 1 | E38: =D42 -> 0.8852 | F38: =E42 -> 0.77544936 | G38: =F42 -> 0.67161458 | H38: =G42 -> 0.57448908 | I38: =H42 -> 0.484763 | J38: =I42 -> 0.40299373 | K38: =J42 -> 0.32957909 | L38: =K42 -> 0.26473538 | ... AB38: =AA42 -> 4.1786061e-05
B39: Muertes (fracción) | D39: =D38*D37 -> 0.1148 | E39: =E38*E37 -> 0.10975064 | F39: =F38*F37 -> 0.10383478 | G39: =G38*G37 -> 0.097125501 | H39: =H38*H37 -> 0.089726079 | I39: =I38*I37 -> 0.081769272 | J39: =J38*J37 -> 0.073414646 | K39: =K38*K37 -> 0.064843705 | ... AB39: =AB38*AB37 -> 3.0418896e-05
B40: Beneficio por muerte bruto (USD mm) | D40: =D39*Cartera!$D$8 -> 9.184 | E40: =E39*Cartera!$D$8 -> 8.7800509 | F40: =F39*Cartera!$D$8 -> 8.3067823 | G40: =G39*Cartera!$D$8 -> 7.7700401 | H40: =H39*Cartera!$D$8 -> 7.1780863 | I40: =I39*Cartera!$D$8 -> 6.5415418 | J40: =J39*Cartera!$D$8 -> 5.8731717 | K40: =K39*Cartera!$D$8 -> 5.1874964 | ... AB40: =AB39*Cartera!$D$8 -> 0.0024335117
